2020-07-27 08:39:52,892 - werkzeug - INFO -  * Running on http://127.0.0.1:5000/ (Press CTRL+C to quit)
2020-07-27 08:39:52,892 - werkzeug - INFO -  * Running on http://127.0.0.1:5000/ (Press CTRL+C to quit)
2020-07-27 08:40:42,046 - werkzeug - INFO - 127.0.0.1 - - [27/Jul/2020 08:40:42] "[33mPOST /app/v1/addmedia HTTP/1.1[0m" 404 -
2020-07-27 08:40:42,046 - werkzeug - INFO - 127.0.0.1 - - [27/Jul/2020 08:40:42] "[33mPOST /app/v1/addmedia HTTP/1.1[0m" 404 -
2020-07-27 08:41:12,699 - werkzeug - INFO - 127.0.0.1 - - [27/Jul/2020 08:41:12] "[33mPOST /app/v1/addmedia HTTP/1.1[0m" 404 -
2020-07-27 08:41:12,699 - werkzeug - INFO - 127.0.0.1 - - [27/Jul/2020 08:41:12] "[33mPOST /app/v1/addmedia HTTP/1.1[0m" 404 -
2020-07-27 08:41:20,466 - werkzeug - INFO - 127.0.0.1 - - [27/Jul/2020 08:41:20] "[33mPOST /app/v1/addmedia HTTP/1.1[0m" 404 -
2020-07-27 08:41:20,466 - werkzeug - INFO - 127.0.0.1 - - [27/Jul/2020 08:41:20] "[33mPOST /app/v1/addmedia HTTP/1.1[0m" 404 -
2020-07-27 08:42:25,048 - flask.app - ERROR - Exception on /api/v1/addmedia [POST]
Traceback (most recent call last):
  File "C:\Users\vlekkala\AppData\Local\Programs\Python\Python36\lib\site-packages\flask\app.py", line 2311, in wsgi_app
    response = self.full_dispatch_request()
  File "C:\Users\vlekkala\AppData\Local\Programs\Python\Python36\lib\site-packages\flask\app.py", line 1834, in full_dispatch_request
    rv = self.handle_user_exception(e)
  File "C:\Users\vlekkala\AppData\Local\Programs\Python\Python36\lib\site-packages\flask_cors\extension.py", line 161, in wrapped_function
    return cors_after_request(app.make_response(f(*args, **kwargs)))
  File "C:\Users\vlekkala\AppData\Local\Programs\Python\Python36\lib\site-packages\flask\app.py", line 1737, in handle_user_exception
    reraise(exc_type, exc_value, tb)
  File "C:\Users\vlekkala\AppData\Local\Programs\Python\Python36\lib\site-packages\flask\_compat.py", line 36, in reraise
    raise value
  File "C:\Users\vlekkala\AppData\Local\Programs\Python\Python36\lib\site-packages\flask\app.py", line 1832, in full_dispatch_request
    rv = self.dispatch_request()
  File "C:\Users\vlekkala\AppData\Local\Programs\Python\Python36\lib\site-packages\flask\app.py", line 1818, in dispatch_request
    return self.view_functions[rule.endpoint](**req.view_args)
  File "C:\work\github\whereismyshow\DataAccess\main\routes.py", line 20, in add_media
    return jsonify(SaveResult(False, message="request data is not valid"))
  File "C:\Users\vlekkala\AppData\Local\Programs\Python\Python36\lib\site-packages\flask\json\__init__.py", line 351, in jsonify
    dumps(data, indent=indent, separators=separators) + '\n',
  File "C:\Users\vlekkala\AppData\Local\Programs\Python\Python36\lib\site-packages\flask\json\__init__.py", line 194, in dumps
    rv = _json.dumps(obj, **kwargs)
  File "C:\Users\vlekkala\AppData\Local\Programs\Python\Python36\lib\json\__init__.py", line 238, in dumps
    **kw).encode(obj)
  File "C:\Users\vlekkala\AppData\Local\Programs\Python\Python36\lib\json\encoder.py", line 199, in encode
    chunks = self.iterencode(o, _one_shot=True)
  File "C:\Users\vlekkala\AppData\Local\Programs\Python\Python36\lib\json\encoder.py", line 257, in iterencode
    return _iterencode(o, 0)
  File "C:\Users\vlekkala\AppData\Local\Programs\Python\Python36\lib\site-packages\flask\json\__init__.py", line 81, in default
    return _json.JSONEncoder.default(self, o)
  File "C:\Users\vlekkala\AppData\Local\Programs\Python\Python36\lib\json\encoder.py", line 180, in default
    o.__class__.__name__)
TypeError: Object of type 'SaveResult' is not JSON serializable
2020-07-27 08:42:25,048 - flask.app - ERROR - Exception on /api/v1/addmedia [POST]
Traceback (most recent call last):
  File "C:\Users\vlekkala\AppData\Local\Programs\Python\Python36\lib\site-packages\flask\app.py", line 2311, in wsgi_app
    response = self.full_dispatch_request()
  File "C:\Users\vlekkala\AppData\Local\Programs\Python\Python36\lib\site-packages\flask\app.py", line 1834, in full_dispatch_request
    rv = self.handle_user_exception(e)
  File "C:\Users\vlekkala\AppData\Local\Programs\Python\Python36\lib\site-packages\flask_cors\extension.py", line 161, in wrapped_function
    return cors_after_request(app.make_response(f(*args, **kwargs)))
  File "C:\Users\vlekkala\AppData\Local\Programs\Python\Python36\lib\site-packages\flask\app.py", line 1737, in handle_user_exception
    reraise(exc_type, exc_value, tb)
  File "C:\Users\vlekkala\AppData\Local\Programs\Python\Python36\lib\site-packages\flask\_compat.py", line 36, in reraise
    raise value
  File "C:\Users\vlekkala\AppData\Local\Programs\Python\Python36\lib\site-packages\flask\app.py", line 1832, in full_dispatch_request
    rv = self.dispatch_request()
  File "C:\Users\vlekkala\AppData\Local\Programs\Python\Python36\lib\site-packages\flask\app.py", line 1818, in dispatch_request
    return self.view_functions[rule.endpoint](**req.view_args)
  File "C:\work\github\whereismyshow\DataAccess\main\routes.py", line 20, in add_media
    return jsonify(SaveResult(False, message="request data is not valid"))
  File "C:\Users\vlekkala\AppData\Local\Programs\Python\Python36\lib\site-packages\flask\json\__init__.py", line 351, in jsonify
    dumps(data, indent=indent, separators=separators) + '\n',
  File "C:\Users\vlekkala\AppData\Local\Programs\Python\Python36\lib\site-packages\flask\json\__init__.py", line 194, in dumps
    rv = _json.dumps(obj, **kwargs)
  File "C:\Users\vlekkala\AppData\Local\Programs\Python\Python36\lib\json\__init__.py", line 238, in dumps
    **kw).encode(obj)
  File "C:\Users\vlekkala\AppData\Local\Programs\Python\Python36\lib\json\encoder.py", line 199, in encode
    chunks = self.iterencode(o, _one_shot=True)
  File "C:\Users\vlekkala\AppData\Local\Programs\Python\Python36\lib\json\encoder.py", line 257, in iterencode
    return _iterencode(o, 0)
  File "C:\Users\vlekkala\AppData\Local\Programs\Python\Python36\lib\site-packages\flask\json\__init__.py", line 81, in default
    return _json.JSONEncoder.default(self, o)
  File "C:\Users\vlekkala\AppData\Local\Programs\Python\Python36\lib\json\encoder.py", line 180, in default
    o.__class__.__name__)
TypeError: Object of type 'SaveResult' is not JSON serializable
2020-07-27 08:42:25,072 - werkzeug - INFO - 127.0.0.1 - - [27/Jul/2020 08:42:25] "[35m[1mPOST /api/v1/addmedia HTTP/1.1[0m" 500 -
2020-07-27 08:42:25,072 - werkzeug - INFO - 127.0.0.1 - - [27/Jul/2020 08:42:25] "[35m[1mPOST /api/v1/addmedia HTTP/1.1[0m" 500 -
2020-07-27 08:42:58,562 - werkzeug - INFO -  * Running on http://127.0.0.1:5000/ (Press CTRL+C to quit)
2020-07-27 08:42:58,562 - werkzeug - INFO -  * Running on http://127.0.0.1:5000/ (Press CTRL+C to quit)
2020-07-27 08:43:05,229 - flask.app - ERROR - Exception on /api/v1/addmedia [POST]
Traceback (most recent call last):
  File "C:\Users\vlekkala\AppData\Local\Programs\Python\Python36\lib\site-packages\flask\app.py", line 2311, in wsgi_app
    response = self.full_dispatch_request()
  File "C:\Users\vlekkala\AppData\Local\Programs\Python\Python36\lib\site-packages\flask\app.py", line 1834, in full_dispatch_request
    rv = self.handle_user_exception(e)
  File "C:\Users\vlekkala\AppData\Local\Programs\Python\Python36\lib\site-packages\flask_cors\extension.py", line 161, in wrapped_function
    return cors_after_request(app.make_response(f(*args, **kwargs)))
  File "C:\Users\vlekkala\AppData\Local\Programs\Python\Python36\lib\site-packages\flask\app.py", line 1737, in handle_user_exception
    reraise(exc_type, exc_value, tb)
  File "C:\Users\vlekkala\AppData\Local\Programs\Python\Python36\lib\site-packages\flask\_compat.py", line 36, in reraise
    raise value
  File "C:\Users\vlekkala\AppData\Local\Programs\Python\Python36\lib\site-packages\flask\app.py", line 1832, in full_dispatch_request
    rv = self.dispatch_request()
  File "C:\Users\vlekkala\AppData\Local\Programs\Python\Python36\lib\site-packages\flask\app.py", line 1818, in dispatch_request
    return self.view_functions[rule.endpoint](**req.view_args)
  File "C:\work\github\whereismyshow\DataAccess\main\routes.py", line 19, in add_media
    return jsonify(SaveResult(False, message="request data is not valid"))
  File "C:\Users\vlekkala\AppData\Local\Programs\Python\Python36\lib\site-packages\flask\json\__init__.py", line 351, in jsonify
    dumps(data, indent=indent, separators=separators) + '\n',
  File "C:\Users\vlekkala\AppData\Local\Programs\Python\Python36\lib\site-packages\flask\json\__init__.py", line 194, in dumps
    rv = _json.dumps(obj, **kwargs)
  File "C:\Users\vlekkala\AppData\Local\Programs\Python\Python36\lib\json\__init__.py", line 238, in dumps
    **kw).encode(obj)
  File "C:\Users\vlekkala\AppData\Local\Programs\Python\Python36\lib\json\encoder.py", line 199, in encode
    chunks = self.iterencode(o, _one_shot=True)
  File "C:\Users\vlekkala\AppData\Local\Programs\Python\Python36\lib\json\encoder.py", line 257, in iterencode
    return _iterencode(o, 0)
  File "C:\Users\vlekkala\AppData\Local\Programs\Python\Python36\lib\site-packages\flask\json\__init__.py", line 81, in default
    return _json.JSONEncoder.default(self, o)
  File "C:\Users\vlekkala\AppData\Local\Programs\Python\Python36\lib\json\encoder.py", line 180, in default
    o.__class__.__name__)
TypeError: Object of type 'SaveResult' is not JSON serializable
2020-07-27 08:43:05,229 - flask.app - ERROR - Exception on /api/v1/addmedia [POST]
Traceback (most recent call last):
  File "C:\Users\vlekkala\AppData\Local\Programs\Python\Python36\lib\site-packages\flask\app.py", line 2311, in wsgi_app
    response = self.full_dispatch_request()
  File "C:\Users\vlekkala\AppData\Local\Programs\Python\Python36\lib\site-packages\flask\app.py", line 1834, in full_dispatch_request
    rv = self.handle_user_exception(e)
  File "C:\Users\vlekkala\AppData\Local\Programs\Python\Python36\lib\site-packages\flask_cors\extension.py", line 161, in wrapped_function
    return cors_after_request(app.make_response(f(*args, **kwargs)))
  File "C:\Users\vlekkala\AppData\Local\Programs\Python\Python36\lib\site-packages\flask\app.py", line 1737, in handle_user_exception
    reraise(exc_type, exc_value, tb)
  File "C:\Users\vlekkala\AppData\Local\Programs\Python\Python36\lib\site-packages\flask\_compat.py", line 36, in reraise
    raise value
  File "C:\Users\vlekkala\AppData\Local\Programs\Python\Python36\lib\site-packages\flask\app.py", line 1832, in full_dispatch_request
    rv = self.dispatch_request()
  File "C:\Users\vlekkala\AppData\Local\Programs\Python\Python36\lib\site-packages\flask\app.py", line 1818, in dispatch_request
    return self.view_functions[rule.endpoint](**req.view_args)
  File "C:\work\github\whereismyshow\DataAccess\main\routes.py", line 19, in add_media
    return jsonify(SaveResult(False, message="request data is not valid"))
  File "C:\Users\vlekkala\AppData\Local\Programs\Python\Python36\lib\site-packages\flask\json\__init__.py", line 351, in jsonify
    dumps(data, indent=indent, separators=separators) + '\n',
  File "C:\Users\vlekkala\AppData\Local\Programs\Python\Python36\lib\site-packages\flask\json\__init__.py", line 194, in dumps
    rv = _json.dumps(obj, **kwargs)
  File "C:\Users\vlekkala\AppData\Local\Programs\Python\Python36\lib\json\__init__.py", line 238, in dumps
    **kw).encode(obj)
  File "C:\Users\vlekkala\AppData\Local\Programs\Python\Python36\lib\json\encoder.py", line 199, in encode
    chunks = self.iterencode(o, _one_shot=True)
  File "C:\Users\vlekkala\AppData\Local\Programs\Python\Python36\lib\json\encoder.py", line 257, in iterencode
    return _iterencode(o, 0)
  File "C:\Users\vlekkala\AppData\Local\Programs\Python\Python36\lib\site-packages\flask\json\__init__.py", line 81, in default
    return _json.JSONEncoder.default(self, o)
  File "C:\Users\vlekkala\AppData\Local\Programs\Python\Python36\lib\json\encoder.py", line 180, in default
    o.__class__.__name__)
TypeError: Object of type 'SaveResult' is not JSON serializable
2020-07-27 08:43:05,242 - werkzeug - INFO - 127.0.0.1 - - [27/Jul/2020 08:43:05] "[35m[1mPOST /api/v1/addmedia HTTP/1.1[0m" 500 -
2020-07-27 08:43:05,242 - werkzeug - INFO - 127.0.0.1 - - [27/Jul/2020 08:43:05] "[35m[1mPOST /api/v1/addmedia HTTP/1.1[0m" 500 -
2020-07-27 08:43:25,618 - flask.app - ERROR - Exception on /api/v1/addmedia [POST]
Traceback (most recent call last):
  File "C:\Users\vlekkala\AppData\Local\Programs\Python\Python36\lib\site-packages\flask\app.py", line 2311, in wsgi_app
    response = self.full_dispatch_request()
  File "C:\Users\vlekkala\AppData\Local\Programs\Python\Python36\lib\site-packages\flask\app.py", line 1834, in full_dispatch_request
    rv = self.handle_user_exception(e)
  File "C:\Users\vlekkala\AppData\Local\Programs\Python\Python36\lib\site-packages\flask_cors\extension.py", line 161, in wrapped_function
    return cors_after_request(app.make_response(f(*args, **kwargs)))
  File "C:\Users\vlekkala\AppData\Local\Programs\Python\Python36\lib\site-packages\flask\app.py", line 1737, in handle_user_exception
    reraise(exc_type, exc_value, tb)
  File "C:\Users\vlekkala\AppData\Local\Programs\Python\Python36\lib\site-packages\flask\_compat.py", line 36, in reraise
    raise value
  File "C:\Users\vlekkala\AppData\Local\Programs\Python\Python36\lib\site-packages\flask\app.py", line 1832, in full_dispatch_request
    rv = self.dispatch_request()
  File "C:\Users\vlekkala\AppData\Local\Programs\Python\Python36\lib\site-packages\flask\app.py", line 1818, in dispatch_request
    return self.view_functions[rule.endpoint](**req.view_args)
  File "C:\work\github\whereismyshow\DataAccess\main\routes.py", line 19, in add_media
    return jsonify(SaveResult(False, message="request data is not valid"))
  File "C:\Users\vlekkala\AppData\Local\Programs\Python\Python36\lib\site-packages\flask\json\__init__.py", line 351, in jsonify
    dumps(data, indent=indent, separators=separators) + '\n',
  File "C:\Users\vlekkala\AppData\Local\Programs\Python\Python36\lib\site-packages\flask\json\__init__.py", line 194, in dumps
    rv = _json.dumps(obj, **kwargs)
  File "C:\Users\vlekkala\AppData\Local\Programs\Python\Python36\lib\json\__init__.py", line 238, in dumps
    **kw).encode(obj)
  File "C:\Users\vlekkala\AppData\Local\Programs\Python\Python36\lib\json\encoder.py", line 199, in encode
    chunks = self.iterencode(o, _one_shot=True)
  File "C:\Users\vlekkala\AppData\Local\Programs\Python\Python36\lib\json\encoder.py", line 257, in iterencode
    return _iterencode(o, 0)
  File "C:\Users\vlekkala\AppData\Local\Programs\Python\Python36\lib\site-packages\flask\json\__init__.py", line 81, in default
    return _json.JSONEncoder.default(self, o)
  File "C:\Users\vlekkala\AppData\Local\Programs\Python\Python36\lib\json\encoder.py", line 180, in default
    o.__class__.__name__)
TypeError: Object of type 'SaveResult' is not JSON serializable
2020-07-27 08:43:25,618 - flask.app - ERROR - Exception on /api/v1/addmedia [POST]
Traceback (most recent call last):
  File "C:\Users\vlekkala\AppData\Local\Programs\Python\Python36\lib\site-packages\flask\app.py", line 2311, in wsgi_app
    response = self.full_dispatch_request()
  File "C:\Users\vlekkala\AppData\Local\Programs\Python\Python36\lib\site-packages\flask\app.py", line 1834, in full_dispatch_request
    rv = self.handle_user_exception(e)
  File "C:\Users\vlekkala\AppData\Local\Programs\Python\Python36\lib\site-packages\flask_cors\extension.py", line 161, in wrapped_function
    return cors_after_request(app.make_response(f(*args, **kwargs)))
  File "C:\Users\vlekkala\AppData\Local\Programs\Python\Python36\lib\site-packages\flask\app.py", line 1737, in handle_user_exception
    reraise(exc_type, exc_value, tb)
  File "C:\Users\vlekkala\AppData\Local\Programs\Python\Python36\lib\site-packages\flask\_compat.py", line 36, in reraise
    raise value
  File "C:\Users\vlekkala\AppData\Local\Programs\Python\Python36\lib\site-packages\flask\app.py", line 1832, in full_dispatch_request
    rv = self.dispatch_request()
  File "C:\Users\vlekkala\AppData\Local\Programs\Python\Python36\lib\site-packages\flask\app.py", line 1818, in dispatch_request
    return self.view_functions[rule.endpoint](**req.view_args)
  File "C:\work\github\whereismyshow\DataAccess\main\routes.py", line 19, in add_media
    return jsonify(SaveResult(False, message="request data is not valid"))
  File "C:\Users\vlekkala\AppData\Local\Programs\Python\Python36\lib\site-packages\flask\json\__init__.py", line 351, in jsonify
    dumps(data, indent=indent, separators=separators) + '\n',
  File "C:\Users\vlekkala\AppData\Local\Programs\Python\Python36\lib\site-packages\flask\json\__init__.py", line 194, in dumps
    rv = _json.dumps(obj, **kwargs)
  File "C:\Users\vlekkala\AppData\Local\Programs\Python\Python36\lib\json\__init__.py", line 238, in dumps
    **kw).encode(obj)
  File "C:\Users\vlekkala\AppData\Local\Programs\Python\Python36\lib\json\encoder.py", line 199, in encode
    chunks = self.iterencode(o, _one_shot=True)
  File "C:\Users\vlekkala\AppData\Local\Programs\Python\Python36\lib\json\encoder.py", line 257, in iterencode
    return _iterencode(o, 0)
  File "C:\Users\vlekkala\AppData\Local\Programs\Python\Python36\lib\site-packages\flask\json\__init__.py", line 81, in default
    return _json.JSONEncoder.default(self, o)
  File "C:\Users\vlekkala\AppData\Local\Programs\Python\Python36\lib\json\encoder.py", line 180, in default
    o.__class__.__name__)
TypeError: Object of type 'SaveResult' is not JSON serializable
2020-07-27 08:43:25,623 - werkzeug - INFO - 127.0.0.1 - - [27/Jul/2020 08:43:25] "[35m[1mPOST /api/v1/addmedia HTTP/1.1[0m" 500 -
2020-07-27 08:43:25,623 - werkzeug - INFO - 127.0.0.1 - - [27/Jul/2020 08:43:25] "[35m[1mPOST /api/v1/addmedia HTTP/1.1[0m" 500 -
2020-07-27 08:43:27,271 - flask.app - ERROR - Exception on /api/v1/addmedia [POST]
Traceback (most recent call last):
  File "C:\Users\vlekkala\AppData\Local\Programs\Python\Python36\lib\site-packages\flask\app.py", line 2311, in wsgi_app
    response = self.full_dispatch_request()
  File "C:\Users\vlekkala\AppData\Local\Programs\Python\Python36\lib\site-packages\flask\app.py", line 1834, in full_dispatch_request
    rv = self.handle_user_exception(e)
  File "C:\Users\vlekkala\AppData\Local\Programs\Python\Python36\lib\site-packages\flask_cors\extension.py", line 161, in wrapped_function
    return cors_after_request(app.make_response(f(*args, **kwargs)))
  File "C:\Users\vlekkala\AppData\Local\Programs\Python\Python36\lib\site-packages\flask\app.py", line 1737, in handle_user_exception
    reraise(exc_type, exc_value, tb)
  File "C:\Users\vlekkala\AppData\Local\Programs\Python\Python36\lib\site-packages\flask\_compat.py", line 36, in reraise
    raise value
  File "C:\Users\vlekkala\AppData\Local\Programs\Python\Python36\lib\site-packages\flask\app.py", line 1832, in full_dispatch_request
    rv = self.dispatch_request()
  File "C:\Users\vlekkala\AppData\Local\Programs\Python\Python36\lib\site-packages\flask\app.py", line 1818, in dispatch_request
    return self.view_functions[rule.endpoint](**req.view_args)
  File "C:\work\github\whereismyshow\DataAccess\main\routes.py", line 19, in add_media
    return jsonify(SaveResult(False, message="request data is not valid"))
  File "C:\Users\vlekkala\AppData\Local\Programs\Python\Python36\lib\site-packages\flask\json\__init__.py", line 351, in jsonify
    dumps(data, indent=indent, separators=separators) + '\n',
  File "C:\Users\vlekkala\AppData\Local\Programs\Python\Python36\lib\site-packages\flask\json\__init__.py", line 194, in dumps
    rv = _json.dumps(obj, **kwargs)
  File "C:\Users\vlekkala\AppData\Local\Programs\Python\Python36\lib\json\__init__.py", line 238, in dumps
    **kw).encode(obj)
  File "C:\Users\vlekkala\AppData\Local\Programs\Python\Python36\lib\json\encoder.py", line 199, in encode
    chunks = self.iterencode(o, _one_shot=True)
  File "C:\Users\vlekkala\AppData\Local\Programs\Python\Python36\lib\json\encoder.py", line 257, in iterencode
    return _iterencode(o, 0)
  File "C:\Users\vlekkala\AppData\Local\Programs\Python\Python36\lib\site-packages\flask\json\__init__.py", line 81, in default
    return _json.JSONEncoder.default(self, o)
  File "C:\Users\vlekkala\AppData\Local\Programs\Python\Python36\lib\json\encoder.py", line 180, in default
    o.__class__.__name__)
TypeError: Object of type 'SaveResult' is not JSON serializable
2020-07-27 08:43:27,271 - flask.app - ERROR - Exception on /api/v1/addmedia [POST]
Traceback (most recent call last):
  File "C:\Users\vlekkala\AppData\Local\Programs\Python\Python36\lib\site-packages\flask\app.py", line 2311, in wsgi_app
    response = self.full_dispatch_request()
  File "C:\Users\vlekkala\AppData\Local\Programs\Python\Python36\lib\site-packages\flask\app.py", line 1834, in full_dispatch_request
    rv = self.handle_user_exception(e)
  File "C:\Users\vlekkala\AppData\Local\Programs\Python\Python36\lib\site-packages\flask_cors\extension.py", line 161, in wrapped_function
    return cors_after_request(app.make_response(f(*args, **kwargs)))
  File "C:\Users\vlekkala\AppData\Local\Programs\Python\Python36\lib\site-packages\flask\app.py", line 1737, in handle_user_exception
    reraise(exc_type, exc_value, tb)
  File "C:\Users\vlekkala\AppData\Local\Programs\Python\Python36\lib\site-packages\flask\_compat.py", line 36, in reraise
    raise value
  File "C:\Users\vlekkala\AppData\Local\Programs\Python\Python36\lib\site-packages\flask\app.py", line 1832, in full_dispatch_request
    rv = self.dispatch_request()
  File "C:\Users\vlekkala\AppData\Local\Programs\Python\Python36\lib\site-packages\flask\app.py", line 1818, in dispatch_request
    return self.view_functions[rule.endpoint](**req.view_args)
  File "C:\work\github\whereismyshow\DataAccess\main\routes.py", line 19, in add_media
    return jsonify(SaveResult(False, message="request data is not valid"))
  File "C:\Users\vlekkala\AppData\Local\Programs\Python\Python36\lib\site-packages\flask\json\__init__.py", line 351, in jsonify
    dumps(data, indent=indent, separators=separators) + '\n',
  File "C:\Users\vlekkala\AppData\Local\Programs\Python\Python36\lib\site-packages\flask\json\__init__.py", line 194, in dumps
    rv = _json.dumps(obj, **kwargs)
  File "C:\Users\vlekkala\AppData\Local\Programs\Python\Python36\lib\json\__init__.py", line 238, in dumps
    **kw).encode(obj)
  File "C:\Users\vlekkala\AppData\Local\Programs\Python\Python36\lib\json\encoder.py", line 199, in encode
    chunks = self.iterencode(o, _one_shot=True)
  File "C:\Users\vlekkala\AppData\Local\Programs\Python\Python36\lib\json\encoder.py", line 257, in iterencode
    return _iterencode(o, 0)
  File "C:\Users\vlekkala\AppData\Local\Programs\Python\Python36\lib\site-packages\flask\json\__init__.py", line 81, in default
    return _json.JSONEncoder.default(self, o)
  File "C:\Users\vlekkala\AppData\Local\Programs\Python\Python36\lib\json\encoder.py", line 180, in default
    o.__class__.__name__)
TypeError: Object of type 'SaveResult' is not JSON serializable
2020-07-27 08:43:27,288 - werkzeug - INFO - 127.0.0.1 - - [27/Jul/2020 08:43:27] "[35m[1mPOST /api/v1/addmedia HTTP/1.1[0m" 500 -
2020-07-27 08:43:27,288 - werkzeug - INFO - 127.0.0.1 - - [27/Jul/2020 08:43:27] "[35m[1mPOST /api/v1/addmedia HTTP/1.1[0m" 500 -
2020-07-27 08:45:45,516 - werkzeug - INFO -  * Running on http://127.0.0.1:5000/ (Press CTRL+C to quit)
2020-07-27 08:45:45,516 - werkzeug - INFO -  * Running on http://127.0.0.1:5000/ (Press CTRL+C to quit)
2020-07-27 08:45:59,658 - werkzeug - INFO -  * Running on http://127.0.0.1:5000/ (Press CTRL+C to quit)
2020-07-27 08:45:59,658 - werkzeug - INFO -  * Running on http://127.0.0.1:5000/ (Press CTRL+C to quit)
2020-07-27 08:46:14,210 - werkzeug - INFO -  * Running on http://127.0.0.1:5000/ (Press CTRL+C to quit)
2020-07-27 08:46:14,210 - werkzeug - INFO -  * Running on http://127.0.0.1:5000/ (Press CTRL+C to quit)
2020-07-27 08:46:47,398 - werkzeug - INFO -  * Running on http://127.0.0.1:5000/ (Press CTRL+C to quit)
2020-07-27 08:46:47,398 - werkzeug - INFO -  * Running on http://127.0.0.1:5000/ (Press CTRL+C to quit)
2020-07-27 08:46:58,485 - flask.app - ERROR - Exception on /api/v1/addmedia [POST]
Traceback (most recent call last):
  File "C:\Users\vlekkala\AppData\Local\Programs\Python\Python36\lib\site-packages\flask\app.py", line 2311, in wsgi_app
    response = self.full_dispatch_request()
  File "C:\Users\vlekkala\AppData\Local\Programs\Python\Python36\lib\site-packages\flask\app.py", line 1834, in full_dispatch_request
    rv = self.handle_user_exception(e)
  File "C:\Users\vlekkala\AppData\Local\Programs\Python\Python36\lib\site-packages\flask_cors\extension.py", line 161, in wrapped_function
    return cors_after_request(app.make_response(f(*args, **kwargs)))
  File "C:\Users\vlekkala\AppData\Local\Programs\Python\Python36\lib\site-packages\flask\app.py", line 1737, in handle_user_exception
    reraise(exc_type, exc_value, tb)
  File "C:\Users\vlekkala\AppData\Local\Programs\Python\Python36\lib\site-packages\flask\_compat.py", line 36, in reraise
    raise value
  File "C:\Users\vlekkala\AppData\Local\Programs\Python\Python36\lib\site-packages\flask\app.py", line 1832, in full_dispatch_request
    rv = self.dispatch_request()
  File "C:\Users\vlekkala\AppData\Local\Programs\Python\Python36\lib\site-packages\flask\app.py", line 1818, in dispatch_request
    return self.view_functions[rule.endpoint](**req.view_args)
  File "C:\work\github\whereismyshow\DataAccess\main\routes.py", line 19, in add_media
    return jsonify(SaveResult(False, message="request data is not valid"))
  File "C:\Users\vlekkala\AppData\Local\Programs\Python\Python36\lib\site-packages\flask\json\__init__.py", line 351, in jsonify
    dumps(data, indent=indent, separators=separators) + '\n',
  File "C:\Users\vlekkala\AppData\Local\Programs\Python\Python36\lib\site-packages\flask\json\__init__.py", line 194, in dumps
    rv = _json.dumps(obj, **kwargs)
  File "C:\Users\vlekkala\AppData\Local\Programs\Python\Python36\lib\json\__init__.py", line 238, in dumps
    **kw).encode(obj)
  File "C:\Users\vlekkala\AppData\Local\Programs\Python\Python36\lib\json\encoder.py", line 199, in encode
    chunks = self.iterencode(o, _one_shot=True)
  File "C:\Users\vlekkala\AppData\Local\Programs\Python\Python36\lib\json\encoder.py", line 257, in iterencode
    return _iterencode(o, 0)
  File "C:\Users\vlekkala\AppData\Local\Programs\Python\Python36\lib\site-packages\flask\json\__init__.py", line 81, in default
    return _json.JSONEncoder.default(self, o)
  File "C:\Users\vlekkala\AppData\Local\Programs\Python\Python36\lib\json\encoder.py", line 180, in default
    o.__class__.__name__)
TypeError: Object of type 'SaveResult' is not JSON serializable
2020-07-27 08:46:58,485 - flask.app - ERROR - Exception on /api/v1/addmedia [POST]
Traceback (most recent call last):
  File "C:\Users\vlekkala\AppData\Local\Programs\Python\Python36\lib\site-packages\flask\app.py", line 2311, in wsgi_app
    response = self.full_dispatch_request()
  File "C:\Users\vlekkala\AppData\Local\Programs\Python\Python36\lib\site-packages\flask\app.py", line 1834, in full_dispatch_request
    rv = self.handle_user_exception(e)
  File "C:\Users\vlekkala\AppData\Local\Programs\Python\Python36\lib\site-packages\flask_cors\extension.py", line 161, in wrapped_function
    return cors_after_request(app.make_response(f(*args, **kwargs)))
  File "C:\Users\vlekkala\AppData\Local\Programs\Python\Python36\lib\site-packages\flask\app.py", line 1737, in handle_user_exception
    reraise(exc_type, exc_value, tb)
  File "C:\Users\vlekkala\AppData\Local\Programs\Python\Python36\lib\site-packages\flask\_compat.py", line 36, in reraise
    raise value
  File "C:\Users\vlekkala\AppData\Local\Programs\Python\Python36\lib\site-packages\flask\app.py", line 1832, in full_dispatch_request
    rv = self.dispatch_request()
  File "C:\Users\vlekkala\AppData\Local\Programs\Python\Python36\lib\site-packages\flask\app.py", line 1818, in dispatch_request
    return self.view_functions[rule.endpoint](**req.view_args)
  File "C:\work\github\whereismyshow\DataAccess\main\routes.py", line 19, in add_media
    return jsonify(SaveResult(False, message="request data is not valid"))
  File "C:\Users\vlekkala\AppData\Local\Programs\Python\Python36\lib\site-packages\flask\json\__init__.py", line 351, in jsonify
    dumps(data, indent=indent, separators=separators) + '\n',
  File "C:\Users\vlekkala\AppData\Local\Programs\Python\Python36\lib\site-packages\flask\json\__init__.py", line 194, in dumps
    rv = _json.dumps(obj, **kwargs)
  File "C:\Users\vlekkala\AppData\Local\Programs\Python\Python36\lib\json\__init__.py", line 238, in dumps
    **kw).encode(obj)
  File "C:\Users\vlekkala\AppData\Local\Programs\Python\Python36\lib\json\encoder.py", line 199, in encode
    chunks = self.iterencode(o, _one_shot=True)
  File "C:\Users\vlekkala\AppData\Local\Programs\Python\Python36\lib\json\encoder.py", line 257, in iterencode
    return _iterencode(o, 0)
  File "C:\Users\vlekkala\AppData\Local\Programs\Python\Python36\lib\site-packages\flask\json\__init__.py", line 81, in default
    return _json.JSONEncoder.default(self, o)
  File "C:\Users\vlekkala\AppData\Local\Programs\Python\Python36\lib\json\encoder.py", line 180, in default
    o.__class__.__name__)
TypeError: Object of type 'SaveResult' is not JSON serializable
2020-07-27 08:46:58,498 - werkzeug - INFO - 127.0.0.1 - - [27/Jul/2020 08:46:58] "[35m[1mPOST /api/v1/addmedia HTTP/1.1[0m" 500 -
2020-07-27 08:46:58,498 - werkzeug - INFO - 127.0.0.1 - - [27/Jul/2020 08:46:58] "[35m[1mPOST /api/v1/addmedia HTTP/1.1[0m" 500 -
2020-07-27 08:50:01,090 - werkzeug - INFO -  * Running on http://127.0.0.1:5000/ (Press CTRL+C to quit)
2020-07-27 08:50:01,090 - werkzeug - INFO -  * Running on http://127.0.0.1:5000/ (Press CTRL+C to quit)
2020-07-27 08:50:06,728 - flask.app - ERROR - Exception on /api/v1/addmedia [POST]
Traceback (most recent call last):
  File "C:\work\github\whereismyshow\DataAccess\main\routes.py", line 19, in add_media
    return jsonify(SaveResult(False, message="request data is not valid"))
  File "C:\Users\vlekkala\AppData\Local\Programs\Python\Python36\lib\site-packages\flask\json\__init__.py", line 351, in jsonify
    dumps(data, indent=indent, separators=separators) + '\n',
  File "C:\Users\vlekkala\AppData\Local\Programs\Python\Python36\lib\site-packages\flask\json\__init__.py", line 194, in dumps
    rv = _json.dumps(obj, **kwargs)
  File "C:\Users\vlekkala\AppData\Local\Programs\Python\Python36\lib\json\__init__.py", line 238, in dumps
    **kw).encode(obj)
  File "C:\Users\vlekkala\AppData\Local\Programs\Python\Python36\lib\json\encoder.py", line 199, in encode
    chunks = self.iterencode(o, _one_shot=True)
  File "C:\Users\vlekkala\AppData\Local\Programs\Python\Python36\lib\json\encoder.py", line 257, in iterencode
    return _iterencode(o, 0)
  File "C:\Users\vlekkala\AppData\Local\Programs\Python\Python36\lib\site-packages\flask\json\__init__.py", line 81, in default
    return _json.JSONEncoder.default(self, o)
  File "C:\Users\vlekkala\AppData\Local\Programs\Python\Python36\lib\json\encoder.py", line 180, in default
    o.__class__.__name__)
TypeError: Object of type 'SaveResult' is not JSON serializable

During handling of the above exception, another exception occurred:

Traceback (most recent call last):
  File "C:\Users\vlekkala\AppData\Local\Programs\Python\Python36\lib\site-packages\flask\app.py", line 2311, in wsgi_app
    response = self.full_dispatch_request()
  File "C:\Users\vlekkala\AppData\Local\Programs\Python\Python36\lib\site-packages\flask\app.py", line 1834, in full_dispatch_request
    rv = self.handle_user_exception(e)
  File "C:\Users\vlekkala\AppData\Local\Programs\Python\Python36\lib\site-packages\flask_cors\extension.py", line 161, in wrapped_function
    return cors_after_request(app.make_response(f(*args, **kwargs)))
  File "C:\Users\vlekkala\AppData\Local\Programs\Python\Python36\lib\site-packages\flask\app.py", line 1737, in handle_user_exception
    reraise(exc_type, exc_value, tb)
  File "C:\Users\vlekkala\AppData\Local\Programs\Python\Python36\lib\site-packages\flask\_compat.py", line 36, in reraise
    raise value
  File "C:\Users\vlekkala\AppData\Local\Programs\Python\Python36\lib\site-packages\flask\app.py", line 1832, in full_dispatch_request
    rv = self.dispatch_request()
  File "C:\Users\vlekkala\AppData\Local\Programs\Python\Python36\lib\site-packages\flask\app.py", line 1818, in dispatch_request
    return self.view_functions[rule.endpoint](**req.view_args)
  File "C:\work\github\whereismyshow\DataAccess\main\routes.py", line 22, in add_media
    return  jsonify(SaveResult(False, "Exception while processing your request", ex))
  File "C:\Users\vlekkala\AppData\Local\Programs\Python\Python36\lib\site-packages\flask\json\__init__.py", line 351, in jsonify
    dumps(data, indent=indent, separators=separators) + '\n',
  File "C:\Users\vlekkala\AppData\Local\Programs\Python\Python36\lib\site-packages\flask\json\__init__.py", line 194, in dumps
    rv = _json.dumps(obj, **kwargs)
  File "C:\Users\vlekkala\AppData\Local\Programs\Python\Python36\lib\json\__init__.py", line 238, in dumps
    **kw).encode(obj)
  File "C:\Users\vlekkala\AppData\Local\Programs\Python\Python36\lib\json\encoder.py", line 199, in encode
    chunks = self.iterencode(o, _one_shot=True)
  File "C:\Users\vlekkala\AppData\Local\Programs\Python\Python36\lib\json\encoder.py", line 257, in iterencode
    return _iterencode(o, 0)
  File "C:\Users\vlekkala\AppData\Local\Programs\Python\Python36\lib\site-packages\flask\json\__init__.py", line 81, in default
    return _json.JSONEncoder.default(self, o)
  File "C:\Users\vlekkala\AppData\Local\Programs\Python\Python36\lib\json\encoder.py", line 180, in default
    o.__class__.__name__)
TypeError: Object of type 'SaveResult' is not JSON serializable
2020-07-27 08:50:06,728 - flask.app - ERROR - Exception on /api/v1/addmedia [POST]
Traceback (most recent call last):
  File "C:\work\github\whereismyshow\DataAccess\main\routes.py", line 19, in add_media
    return jsonify(SaveResult(False, message="request data is not valid"))
  File "C:\Users\vlekkala\AppData\Local\Programs\Python\Python36\lib\site-packages\flask\json\__init__.py", line 351, in jsonify
    dumps(data, indent=indent, separators=separators) + '\n',
  File "C:\Users\vlekkala\AppData\Local\Programs\Python\Python36\lib\site-packages\flask\json\__init__.py", line 194, in dumps
    rv = _json.dumps(obj, **kwargs)
  File "C:\Users\vlekkala\AppData\Local\Programs\Python\Python36\lib\json\__init__.py", line 238, in dumps
    **kw).encode(obj)
  File "C:\Users\vlekkala\AppData\Local\Programs\Python\Python36\lib\json\encoder.py", line 199, in encode
    chunks = self.iterencode(o, _one_shot=True)
  File "C:\Users\vlekkala\AppData\Local\Programs\Python\Python36\lib\json\encoder.py", line 257, in iterencode
    return _iterencode(o, 0)
  File "C:\Users\vlekkala\AppData\Local\Programs\Python\Python36\lib\site-packages\flask\json\__init__.py", line 81, in default
    return _json.JSONEncoder.default(self, o)
  File "C:\Users\vlekkala\AppData\Local\Programs\Python\Python36\lib\json\encoder.py", line 180, in default
    o.__class__.__name__)
TypeError: Object of type 'SaveResult' is not JSON serializable

During handling of the above exception, another exception occurred:

Traceback (most recent call last):
  File "C:\Users\vlekkala\AppData\Local\Programs\Python\Python36\lib\site-packages\flask\app.py", line 2311, in wsgi_app
    response = self.full_dispatch_request()
  File "C:\Users\vlekkala\AppData\Local\Programs\Python\Python36\lib\site-packages\flask\app.py", line 1834, in full_dispatch_request
    rv = self.handle_user_exception(e)
  File "C:\Users\vlekkala\AppData\Local\Programs\Python\Python36\lib\site-packages\flask_cors\extension.py", line 161, in wrapped_function
    return cors_after_request(app.make_response(f(*args, **kwargs)))
  File "C:\Users\vlekkala\AppData\Local\Programs\Python\Python36\lib\site-packages\flask\app.py", line 1737, in handle_user_exception
    reraise(exc_type, exc_value, tb)
  File "C:\Users\vlekkala\AppData\Local\Programs\Python\Python36\lib\site-packages\flask\_compat.py", line 36, in reraise
    raise value
  File "C:\Users\vlekkala\AppData\Local\Programs\Python\Python36\lib\site-packages\flask\app.py", line 1832, in full_dispatch_request
    rv = self.dispatch_request()
  File "C:\Users\vlekkala\AppData\Local\Programs\Python\Python36\lib\site-packages\flask\app.py", line 1818, in dispatch_request
    return self.view_functions[rule.endpoint](**req.view_args)
  File "C:\work\github\whereismyshow\DataAccess\main\routes.py", line 22, in add_media
    return  jsonify(SaveResult(False, "Exception while processing your request", ex))
  File "C:\Users\vlekkala\AppData\Local\Programs\Python\Python36\lib\site-packages\flask\json\__init__.py", line 351, in jsonify
    dumps(data, indent=indent, separators=separators) + '\n',
  File "C:\Users\vlekkala\AppData\Local\Programs\Python\Python36\lib\site-packages\flask\json\__init__.py", line 194, in dumps
    rv = _json.dumps(obj, **kwargs)
  File "C:\Users\vlekkala\AppData\Local\Programs\Python\Python36\lib\json\__init__.py", line 238, in dumps
    **kw).encode(obj)
  File "C:\Users\vlekkala\AppData\Local\Programs\Python\Python36\lib\json\encoder.py", line 199, in encode
    chunks = self.iterencode(o, _one_shot=True)
  File "C:\Users\vlekkala\AppData\Local\Programs\Python\Python36\lib\json\encoder.py", line 257, in iterencode
    return _iterencode(o, 0)
  File "C:\Users\vlekkala\AppData\Local\Programs\Python\Python36\lib\site-packages\flask\json\__init__.py", line 81, in default
    return _json.JSONEncoder.default(self, o)
  File "C:\Users\vlekkala\AppData\Local\Programs\Python\Python36\lib\json\encoder.py", line 180, in default
    o.__class__.__name__)
TypeError: Object of type 'SaveResult' is not JSON serializable
2020-07-27 08:50:06,742 - werkzeug - INFO - 127.0.0.1 - - [27/Jul/2020 08:50:06] "[35m[1mPOST /api/v1/addmedia HTTP/1.1[0m" 500 -
2020-07-27 08:50:06,742 - werkzeug - INFO - 127.0.0.1 - - [27/Jul/2020 08:50:06] "[35m[1mPOST /api/v1/addmedia HTTP/1.1[0m" 500 -
2020-07-27 08:51:05,143 - werkzeug - INFO -  * Running on http://127.0.0.1:5000/ (Press CTRL+C to quit)
2020-07-27 08:51:05,143 - werkzeug - INFO -  * Running on http://127.0.0.1:5000/ (Press CTRL+C to quit)
2020-07-27 08:51:38,576 - flask.app - ERROR - Exception on /api/v1/addmedia [POST]
Traceback (most recent call last):
  File "C:\work\github\whereismyshow\DataAccess\main\routes.py", line 19, in add_media
    return jsonify(SaveResult(False, message="request data is not valid"))
  File "C:\Users\vlekkala\AppData\Local\Programs\Python\Python36\lib\site-packages\flask\json\__init__.py", line 351, in jsonify
    dumps(data, indent=indent, separators=separators) + '\n',
  File "C:\Users\vlekkala\AppData\Local\Programs\Python\Python36\lib\site-packages\flask\json\__init__.py", line 194, in dumps
    rv = _json.dumps(obj, **kwargs)
  File "C:\Users\vlekkala\AppData\Local\Programs\Python\Python36\lib\json\__init__.py", line 238, in dumps
    **kw).encode(obj)
  File "C:\Users\vlekkala\AppData\Local\Programs\Python\Python36\lib\json\encoder.py", line 199, in encode
    chunks = self.iterencode(o, _one_shot=True)
  File "C:\Users\vlekkala\AppData\Local\Programs\Python\Python36\lib\json\encoder.py", line 257, in iterencode
    return _iterencode(o, 0)
  File "C:\Users\vlekkala\AppData\Local\Programs\Python\Python36\lib\site-packages\flask\json\__init__.py", line 81, in default
    return _json.JSONEncoder.default(self, o)
  File "C:\Users\vlekkala\AppData\Local\Programs\Python\Python36\lib\json\encoder.py", line 180, in default
    o.__class__.__name__)
TypeError: Object of type 'SaveResult' is not JSON serializable

During handling of the above exception, another exception occurred:

Traceback (most recent call last):
  File "C:\Users\vlekkala\AppData\Local\Programs\Python\Python36\lib\site-packages\flask\app.py", line 2311, in wsgi_app
    response = self.full_dispatch_request()
  File "C:\Users\vlekkala\AppData\Local\Programs\Python\Python36\lib\site-packages\flask\app.py", line 1834, in full_dispatch_request
    rv = self.handle_user_exception(e)
  File "C:\Users\vlekkala\AppData\Local\Programs\Python\Python36\lib\site-packages\flask_cors\extension.py", line 161, in wrapped_function
    return cors_after_request(app.make_response(f(*args, **kwargs)))
  File "C:\Users\vlekkala\AppData\Local\Programs\Python\Python36\lib\site-packages\flask\app.py", line 1737, in handle_user_exception
    reraise(exc_type, exc_value, tb)
  File "C:\Users\vlekkala\AppData\Local\Programs\Python\Python36\lib\site-packages\flask\_compat.py", line 36, in reraise
    raise value
  File "C:\Users\vlekkala\AppData\Local\Programs\Python\Python36\lib\site-packages\flask\app.py", line 1832, in full_dispatch_request
    rv = self.dispatch_request()
  File "C:\Users\vlekkala\AppData\Local\Programs\Python\Python36\lib\site-packages\flask\app.py", line 1818, in dispatch_request
    return self.view_functions[rule.endpoint](**req.view_args)
  File "C:\work\github\whereismyshow\DataAccess\main\routes.py", line 22, in add_media
    return  jsonify(SaveResult(False, "Exception while processing your request", ex))
  File "C:\Users\vlekkala\AppData\Local\Programs\Python\Python36\lib\site-packages\flask\json\__init__.py", line 351, in jsonify
    dumps(data, indent=indent, separators=separators) + '\n',
  File "C:\Users\vlekkala\AppData\Local\Programs\Python\Python36\lib\site-packages\flask\json\__init__.py", line 194, in dumps
    rv = _json.dumps(obj, **kwargs)
  File "C:\Users\vlekkala\AppData\Local\Programs\Python\Python36\lib\json\__init__.py", line 238, in dumps
    **kw).encode(obj)
  File "C:\Users\vlekkala\AppData\Local\Programs\Python\Python36\lib\json\encoder.py", line 199, in encode
    chunks = self.iterencode(o, _one_shot=True)
  File "C:\Users\vlekkala\AppData\Local\Programs\Python\Python36\lib\json\encoder.py", line 257, in iterencode
    return _iterencode(o, 0)
  File "C:\Users\vlekkala\AppData\Local\Programs\Python\Python36\lib\site-packages\flask\json\__init__.py", line 81, in default
    return _json.JSONEncoder.default(self, o)
  File "C:\Users\vlekkala\AppData\Local\Programs\Python\Python36\lib\json\encoder.py", line 180, in default
    o.__class__.__name__)
TypeError: Object of type 'SaveResult' is not JSON serializable
2020-07-27 08:51:38,576 - flask.app - ERROR - Exception on /api/v1/addmedia [POST]
Traceback (most recent call last):
  File "C:\work\github\whereismyshow\DataAccess\main\routes.py", line 19, in add_media
    return jsonify(SaveResult(False, message="request data is not valid"))
  File "C:\Users\vlekkala\AppData\Local\Programs\Python\Python36\lib\site-packages\flask\json\__init__.py", line 351, in jsonify
    dumps(data, indent=indent, separators=separators) + '\n',
  File "C:\Users\vlekkala\AppData\Local\Programs\Python\Python36\lib\site-packages\flask\json\__init__.py", line 194, in dumps
    rv = _json.dumps(obj, **kwargs)
  File "C:\Users\vlekkala\AppData\Local\Programs\Python\Python36\lib\json\__init__.py", line 238, in dumps
    **kw).encode(obj)
  File "C:\Users\vlekkala\AppData\Local\Programs\Python\Python36\lib\json\encoder.py", line 199, in encode
    chunks = self.iterencode(o, _one_shot=True)
  File "C:\Users\vlekkala\AppData\Local\Programs\Python\Python36\lib\json\encoder.py", line 257, in iterencode
    return _iterencode(o, 0)
  File "C:\Users\vlekkala\AppData\Local\Programs\Python\Python36\lib\site-packages\flask\json\__init__.py", line 81, in default
    return _json.JSONEncoder.default(self, o)
  File "C:\Users\vlekkala\AppData\Local\Programs\Python\Python36\lib\json\encoder.py", line 180, in default
    o.__class__.__name__)
TypeError: Object of type 'SaveResult' is not JSON serializable

During handling of the above exception, another exception occurred:

Traceback (most recent call last):
  File "C:\Users\vlekkala\AppData\Local\Programs\Python\Python36\lib\site-packages\flask\app.py", line 2311, in wsgi_app
    response = self.full_dispatch_request()
  File "C:\Users\vlekkala\AppData\Local\Programs\Python\Python36\lib\site-packages\flask\app.py", line 1834, in full_dispatch_request
    rv = self.handle_user_exception(e)
  File "C:\Users\vlekkala\AppData\Local\Programs\Python\Python36\lib\site-packages\flask_cors\extension.py", line 161, in wrapped_function
    return cors_after_request(app.make_response(f(*args, **kwargs)))
  File "C:\Users\vlekkala\AppData\Local\Programs\Python\Python36\lib\site-packages\flask\app.py", line 1737, in handle_user_exception
    reraise(exc_type, exc_value, tb)
  File "C:\Users\vlekkala\AppData\Local\Programs\Python\Python36\lib\site-packages\flask\_compat.py", line 36, in reraise
    raise value
  File "C:\Users\vlekkala\AppData\Local\Programs\Python\Python36\lib\site-packages\flask\app.py", line 1832, in full_dispatch_request
    rv = self.dispatch_request()
  File "C:\Users\vlekkala\AppData\Local\Programs\Python\Python36\lib\site-packages\flask\app.py", line 1818, in dispatch_request
    return self.view_functions[rule.endpoint](**req.view_args)
  File "C:\work\github\whereismyshow\DataAccess\main\routes.py", line 22, in add_media
    return  jsonify(SaveResult(False, "Exception while processing your request", ex))
  File "C:\Users\vlekkala\AppData\Local\Programs\Python\Python36\lib\site-packages\flask\json\__init__.py", line 351, in jsonify
    dumps(data, indent=indent, separators=separators) + '\n',
  File "C:\Users\vlekkala\AppData\Local\Programs\Python\Python36\lib\site-packages\flask\json\__init__.py", line 194, in dumps
    rv = _json.dumps(obj, **kwargs)
  File "C:\Users\vlekkala\AppData\Local\Programs\Python\Python36\lib\json\__init__.py", line 238, in dumps
    **kw).encode(obj)
  File "C:\Users\vlekkala\AppData\Local\Programs\Python\Python36\lib\json\encoder.py", line 199, in encode
    chunks = self.iterencode(o, _one_shot=True)
  File "C:\Users\vlekkala\AppData\Local\Programs\Python\Python36\lib\json\encoder.py", line 257, in iterencode
    return _iterencode(o, 0)
  File "C:\Users\vlekkala\AppData\Local\Programs\Python\Python36\lib\site-packages\flask\json\__init__.py", line 81, in default
    return _json.JSONEncoder.default(self, o)
  File "C:\Users\vlekkala\AppData\Local\Programs\Python\Python36\lib\json\encoder.py", line 180, in default
    o.__class__.__name__)
TypeError: Object of type 'SaveResult' is not JSON serializable
2020-07-27 08:51:38,590 - werkzeug - INFO - 127.0.0.1 - - [27/Jul/2020 08:51:38] "[35m[1mPOST /api/v1/addmedia HTTP/1.1[0m" 500 -
2020-07-27 08:51:38,590 - werkzeug - INFO - 127.0.0.1 - - [27/Jul/2020 08:51:38] "[35m[1mPOST /api/v1/addmedia HTTP/1.1[0m" 500 -
2020-07-27 08:51:48,698 - flask.app - ERROR - Exception on /api/v1/addmedia [POST]
Traceback (most recent call last):
  File "C:\work\github\whereismyshow\DataAccess\main\routes.py", line 19, in add_media
    return jsonify(SaveResult(False, message="request data is not valid"))
  File "C:\Users\vlekkala\AppData\Local\Programs\Python\Python36\lib\site-packages\flask\json\__init__.py", line 351, in jsonify
    dumps(data, indent=indent, separators=separators) + '\n',
  File "C:\Users\vlekkala\AppData\Local\Programs\Python\Python36\lib\site-packages\flask\json\__init__.py", line 194, in dumps
    rv = _json.dumps(obj, **kwargs)
  File "C:\Users\vlekkala\AppData\Local\Programs\Python\Python36\lib\json\__init__.py", line 238, in dumps
    **kw).encode(obj)
  File "C:\Users\vlekkala\AppData\Local\Programs\Python\Python36\lib\json\encoder.py", line 199, in encode
    chunks = self.iterencode(o, _one_shot=True)
  File "C:\Users\vlekkala\AppData\Local\Programs\Python\Python36\lib\json\encoder.py", line 257, in iterencode
    return _iterencode(o, 0)
  File "C:\Users\vlekkala\AppData\Local\Programs\Python\Python36\lib\site-packages\flask\json\__init__.py", line 81, in default
    return _json.JSONEncoder.default(self, o)
  File "C:\Users\vlekkala\AppData\Local\Programs\Python\Python36\lib\json\encoder.py", line 180, in default
    o.__class__.__name__)
TypeError: Object of type 'SaveResult' is not JSON serializable

During handling of the above exception, another exception occurred:

Traceback (most recent call last):
  File "C:\Users\vlekkala\AppData\Local\Programs\Python\Python36\lib\site-packages\flask\app.py", line 2311, in wsgi_app
    response = self.full_dispatch_request()
  File "C:\Users\vlekkala\AppData\Local\Programs\Python\Python36\lib\site-packages\flask\app.py", line 1834, in full_dispatch_request
    rv = self.handle_user_exception(e)
  File "C:\Users\vlekkala\AppData\Local\Programs\Python\Python36\lib\site-packages\flask_cors\extension.py", line 161, in wrapped_function
    return cors_after_request(app.make_response(f(*args, **kwargs)))
  File "C:\Users\vlekkala\AppData\Local\Programs\Python\Python36\lib\site-packages\flask\app.py", line 1737, in handle_user_exception
    reraise(exc_type, exc_value, tb)
  File "C:\Users\vlekkala\AppData\Local\Programs\Python\Python36\lib\site-packages\flask\_compat.py", line 36, in reraise
    raise value
  File "C:\Users\vlekkala\AppData\Local\Programs\Python\Python36\lib\site-packages\flask\app.py", line 1832, in full_dispatch_request
    rv = self.dispatch_request()
  File "C:\Users\vlekkala\AppData\Local\Programs\Python\Python36\lib\site-packages\flask\app.py", line 1818, in dispatch_request
    return self.view_functions[rule.endpoint](**req.view_args)
  File "C:\work\github\whereismyshow\DataAccess\main\routes.py", line 22, in add_media
    return  jsonify(SaveResult(False, "Exception while processing your request", ex))
  File "C:\Users\vlekkala\AppData\Local\Programs\Python\Python36\lib\site-packages\flask\json\__init__.py", line 351, in jsonify
    dumps(data, indent=indent, separators=separators) + '\n',
  File "C:\Users\vlekkala\AppData\Local\Programs\Python\Python36\lib\site-packages\flask\json\__init__.py", line 194, in dumps
    rv = _json.dumps(obj, **kwargs)
  File "C:\Users\vlekkala\AppData\Local\Programs\Python\Python36\lib\json\__init__.py", line 238, in dumps
    **kw).encode(obj)
  File "C:\Users\vlekkala\AppData\Local\Programs\Python\Python36\lib\json\encoder.py", line 199, in encode
    chunks = self.iterencode(o, _one_shot=True)
  File "C:\Users\vlekkala\AppData\Local\Programs\Python\Python36\lib\json\encoder.py", line 257, in iterencode
    return _iterencode(o, 0)
  File "C:\Users\vlekkala\AppData\Local\Programs\Python\Python36\lib\site-packages\flask\json\__init__.py", line 81, in default
    return _json.JSONEncoder.default(self, o)
  File "C:\Users\vlekkala\AppData\Local\Programs\Python\Python36\lib\json\encoder.py", line 180, in default
    o.__class__.__name__)
TypeError: Object of type 'SaveResult' is not JSON serializable
2020-07-27 08:51:48,698 - flask.app - ERROR - Exception on /api/v1/addmedia [POST]
Traceback (most recent call last):
  File "C:\work\github\whereismyshow\DataAccess\main\routes.py", line 19, in add_media
    return jsonify(SaveResult(False, message="request data is not valid"))
  File "C:\Users\vlekkala\AppData\Local\Programs\Python\Python36\lib\site-packages\flask\json\__init__.py", line 351, in jsonify
    dumps(data, indent=indent, separators=separators) + '\n',
  File "C:\Users\vlekkala\AppData\Local\Programs\Python\Python36\lib\site-packages\flask\json\__init__.py", line 194, in dumps
    rv = _json.dumps(obj, **kwargs)
  File "C:\Users\vlekkala\AppData\Local\Programs\Python\Python36\lib\json\__init__.py", line 238, in dumps
    **kw).encode(obj)
  File "C:\Users\vlekkala\AppData\Local\Programs\Python\Python36\lib\json\encoder.py", line 199, in encode
    chunks = self.iterencode(o, _one_shot=True)
  File "C:\Users\vlekkala\AppData\Local\Programs\Python\Python36\lib\json\encoder.py", line 257, in iterencode
    return _iterencode(o, 0)
  File "C:\Users\vlekkala\AppData\Local\Programs\Python\Python36\lib\site-packages\flask\json\__init__.py", line 81, in default
    return _json.JSONEncoder.default(self, o)
  File "C:\Users\vlekkala\AppData\Local\Programs\Python\Python36\lib\json\encoder.py", line 180, in default
    o.__class__.__name__)
TypeError: Object of type 'SaveResult' is not JSON serializable

During handling of the above exception, another exception occurred:

Traceback (most recent call last):
  File "C:\Users\vlekkala\AppData\Local\Programs\Python\Python36\lib\site-packages\flask\app.py", line 2311, in wsgi_app
    response = self.full_dispatch_request()
  File "C:\Users\vlekkala\AppData\Local\Programs\Python\Python36\lib\site-packages\flask\app.py", line 1834, in full_dispatch_request
    rv = self.handle_user_exception(e)
  File "C:\Users\vlekkala\AppData\Local\Programs\Python\Python36\lib\site-packages\flask_cors\extension.py", line 161, in wrapped_function
    return cors_after_request(app.make_response(f(*args, **kwargs)))
  File "C:\Users\vlekkala\AppData\Local\Programs\Python\Python36\lib\site-packages\flask\app.py", line 1737, in handle_user_exception
    reraise(exc_type, exc_value, tb)
  File "C:\Users\vlekkala\AppData\Local\Programs\Python\Python36\lib\site-packages\flask\_compat.py", line 36, in reraise
    raise value
  File "C:\Users\vlekkala\AppData\Local\Programs\Python\Python36\lib\site-packages\flask\app.py", line 1832, in full_dispatch_request
    rv = self.dispatch_request()
  File "C:\Users\vlekkala\AppData\Local\Programs\Python\Python36\lib\site-packages\flask\app.py", line 1818, in dispatch_request
    return self.view_functions[rule.endpoint](**req.view_args)
  File "C:\work\github\whereismyshow\DataAccess\main\routes.py", line 22, in add_media
    return  jsonify(SaveResult(False, "Exception while processing your request", ex))
  File "C:\Users\vlekkala\AppData\Local\Programs\Python\Python36\lib\site-packages\flask\json\__init__.py", line 351, in jsonify
    dumps(data, indent=indent, separators=separators) + '\n',
  File "C:\Users\vlekkala\AppData\Local\Programs\Python\Python36\lib\site-packages\flask\json\__init__.py", line 194, in dumps
    rv = _json.dumps(obj, **kwargs)
  File "C:\Users\vlekkala\AppData\Local\Programs\Python\Python36\lib\json\__init__.py", line 238, in dumps
    **kw).encode(obj)
  File "C:\Users\vlekkala\AppData\Local\Programs\Python\Python36\lib\json\encoder.py", line 199, in encode
    chunks = self.iterencode(o, _one_shot=True)
  File "C:\Users\vlekkala\AppData\Local\Programs\Python\Python36\lib\json\encoder.py", line 257, in iterencode
    return _iterencode(o, 0)
  File "C:\Users\vlekkala\AppData\Local\Programs\Python\Python36\lib\site-packages\flask\json\__init__.py", line 81, in default
    return _json.JSONEncoder.default(self, o)
  File "C:\Users\vlekkala\AppData\Local\Programs\Python\Python36\lib\json\encoder.py", line 180, in default
    o.__class__.__name__)
TypeError: Object of type 'SaveResult' is not JSON serializable
2020-07-27 08:51:48,703 - werkzeug - INFO - 127.0.0.1 - - [27/Jul/2020 08:51:48] "[35m[1mPOST /api/v1/addmedia HTTP/1.1[0m" 500 -
2020-07-27 08:51:48,703 - werkzeug - INFO - 127.0.0.1 - - [27/Jul/2020 08:51:48] "[35m[1mPOST /api/v1/addmedia HTTP/1.1[0m" 500 -
2020-07-27 08:52:52,205 - werkzeug - INFO -  * Restarting with stat
2020-07-27 08:52:52,205 - werkzeug - INFO -  * Restarting with stat
2020-07-27 08:52:54,324 - werkzeug - WARNING -  * Debugger is active!
2020-07-27 08:52:54,324 - werkzeug - WARNING -  * Debugger is active!
2020-07-27 08:52:54,341 - werkzeug - INFO -  * Debugger PIN: 273-249-106
2020-07-27 08:52:54,341 - werkzeug - INFO -  * Debugger PIN: 273-249-106
2020-07-27 08:52:54,359 - werkzeug - INFO -  * Running on http://127.0.0.1:5000/ (Press CTRL+C to quit)
2020-07-27 08:52:54,359 - werkzeug - INFO -  * Running on http://127.0.0.1:5000/ (Press CTRL+C to quit)
2020-07-27 08:55:36,924 - werkzeug - INFO -  * Restarting with stat
2020-07-27 08:55:36,924 - werkzeug - INFO -  * Restarting with stat
2020-07-27 08:55:38,884 - werkzeug - WARNING -  * Debugger is active!
2020-07-27 08:55:38,884 - werkzeug - WARNING -  * Debugger is active!
2020-07-27 08:55:38,892 - werkzeug - INFO -  * Debugger PIN: 273-249-106
2020-07-27 08:55:38,892 - werkzeug - INFO -  * Debugger PIN: 273-249-106
2020-07-27 08:55:38,906 - werkzeug - INFO -  * Running on http://127.0.0.1:5000/ (Press CTRL+C to quit)
2020-07-27 08:55:38,906 - werkzeug - INFO -  * Running on http://127.0.0.1:5000/ (Press CTRL+C to quit)
2020-07-27 08:55:40,011 - werkzeug - INFO - 127.0.0.1 - - [27/Jul/2020 08:55:40] "[37mPOST /api/v1/addmedia HTTP/1.1[0m" 200 -
2020-07-27 08:55:40,011 - werkzeug - INFO - 127.0.0.1 - - [27/Jul/2020 08:55:40] "[37mPOST /api/v1/addmedia HTTP/1.1[0m" 200 -
2020-07-27 08:56:15,356 - werkzeug - INFO -  * Detected change in 'C:\\work\\github\\whereismyshow\\DataAccess\\main\\routes.py', reloading
2020-07-27 08:56:15,356 - werkzeug - INFO -  * Detected change in 'C:\\work\\github\\whereismyshow\\DataAccess\\main\\routes.py', reloading
2020-07-27 08:56:15,454 - werkzeug - INFO -  * Restarting with stat
2020-07-27 08:56:15,454 - werkzeug - INFO -  * Restarting with stat
2020-07-27 08:56:17,761 - werkzeug - WARNING -  * Debugger is active!
2020-07-27 08:56:17,761 - werkzeug - WARNING -  * Debugger is active!
2020-07-27 08:56:17,769 - werkzeug - INFO -  * Debugger PIN: 273-249-106
2020-07-27 08:56:17,769 - werkzeug - INFO -  * Debugger PIN: 273-249-106
2020-07-27 08:56:17,786 - werkzeug - INFO -  * Running on http://127.0.0.1:5000/ (Press CTRL+C to quit)
2020-07-27 08:56:17,786 - werkzeug - INFO -  * Running on http://127.0.0.1:5000/ (Press CTRL+C to quit)
2020-07-27 08:56:43,253 - werkzeug - INFO -  * Detected change in 'C:\\work\\github\\whereismyshow\\DataAccess\\main\\routes.py', reloading
2020-07-27 08:56:43,253 - werkzeug - INFO -  * Detected change in 'C:\\work\\github\\whereismyshow\\DataAccess\\main\\routes.py', reloading
2020-07-27 08:56:43,373 - werkzeug - INFO -  * Restarting with stat
2020-07-27 08:56:43,373 - werkzeug - INFO -  * Restarting with stat
2020-07-27 08:56:45,334 - werkzeug - WARNING -  * Debugger is active!
2020-07-27 08:56:45,334 - werkzeug - WARNING -  * Debugger is active!
2020-07-27 08:56:45,342 - werkzeug - INFO -  * Debugger PIN: 273-249-106
2020-07-27 08:56:45,342 - werkzeug - INFO -  * Debugger PIN: 273-249-106
2020-07-27 08:56:45,357 - werkzeug - INFO -  * Running on http://127.0.0.1:5000/ (Press CTRL+C to quit)
2020-07-27 08:56:45,357 - werkzeug - INFO -  * Running on http://127.0.0.1:5000/ (Press CTRL+C to quit)
2020-07-27 08:56:46,557 - werkzeug - INFO -  * Detected change in 'C:\\work\\github\\whereismyshow\\DataAccess\\main\\routes.py', reloading
2020-07-27 08:56:46,557 - werkzeug - INFO -  * Detected change in 'C:\\work\\github\\whereismyshow\\DataAccess\\main\\routes.py', reloading
2020-07-27 08:56:46,667 - werkzeug - INFO -  * Restarting with stat
2020-07-27 08:56:46,667 - werkzeug - INFO -  * Restarting with stat
2020-07-27 08:56:48,766 - werkzeug - WARNING -  * Debugger is active!
2020-07-27 08:56:48,766 - werkzeug - WARNING -  * Debugger is active!
2020-07-27 08:56:48,773 - werkzeug - INFO -  * Debugger PIN: 273-249-106
2020-07-27 08:56:48,773 - werkzeug - INFO -  * Debugger PIN: 273-249-106
2020-07-27 08:56:48,788 - werkzeug - INFO -  * Running on http://127.0.0.1:5000/ (Press CTRL+C to quit)
2020-07-27 08:56:48,788 - werkzeug - INFO -  * Running on http://127.0.0.1:5000/ (Press CTRL+C to quit)
2020-07-27 09:01:12,461 - root - ERROR - Exception while parsing media json
the JSON object must be str, bytes or bytearray, not 'list'
Traceback (most recent call last):
  File "C:\work\github\whereismyshow\DataAccess\Services\media_service.py", line 48, in add_media
    show_titles = json.loads(media_json)
  File "C:\Users\vlekkala\AppData\Local\Programs\Python\Python36\lib\json\__init__.py", line 348, in loads
    'not {!r}'.format(s.__class__.__name__))
TypeError: the JSON object must be str, bytes or bytearray, not 'list'
2020-07-27 09:01:12,461 - root - ERROR - Exception while parsing media json
the JSON object must be str, bytes or bytearray, not 'list'
Traceback (most recent call last):
  File "C:\work\github\whereismyshow\DataAccess\Services\media_service.py", line 48, in add_media
    show_titles = json.loads(media_json)
  File "C:\Users\vlekkala\AppData\Local\Programs\Python\Python36\lib\json\__init__.py", line 348, in loads
    'not {!r}'.format(s.__class__.__name__))
TypeError: the JSON object must be str, bytes or bytearray, not 'list'
2020-07-27 09:01:12,469 - werkzeug - INFO - 127.0.0.1 - - [27/Jul/2020 09:01:12] "[37mPOST /api/v1/addmedia HTTP/1.1[0m" 200 -
2020-07-27 09:01:12,469 - werkzeug - INFO - 127.0.0.1 - - [27/Jul/2020 09:01:12] "[37mPOST /api/v1/addmedia HTTP/1.1[0m" 200 -
2020-07-27 09:02:16,965 - root - ERROR - Exception while parsing media json
the JSON object must be str, bytes or bytearray, not 'list'
Traceback (most recent call last):
  File "C:\work\github\whereismyshow\DataAccess\Services\media_service.py", line 48, in add_media
    show_titles = json.loads(media_json)
  File "C:\Users\vlekkala\AppData\Local\Programs\Python\Python36\lib\json\__init__.py", line 348, in loads
    'not {!r}'.format(s.__class__.__name__))
TypeError: the JSON object must be str, bytes or bytearray, not 'list'
2020-07-27 09:02:16,965 - root - ERROR - Exception while parsing media json
the JSON object must be str, bytes or bytearray, not 'list'
Traceback (most recent call last):
  File "C:\work\github\whereismyshow\DataAccess\Services\media_service.py", line 48, in add_media
    show_titles = json.loads(media_json)
  File "C:\Users\vlekkala\AppData\Local\Programs\Python\Python36\lib\json\__init__.py", line 348, in loads
    'not {!r}'.format(s.__class__.__name__))
TypeError: the JSON object must be str, bytes or bytearray, not 'list'
2020-07-27 09:02:16,978 - werkzeug - INFO - 127.0.0.1 - - [27/Jul/2020 09:02:16] "[37mPOST /api/v1/addmedia HTTP/1.1[0m" 200 -
2020-07-27 09:02:16,978 - werkzeug - INFO - 127.0.0.1 - - [27/Jul/2020 09:02:16] "[37mPOST /api/v1/addmedia HTTP/1.1[0m" 200 -
2020-07-27 09:03:07,863 - werkzeug - INFO - 127.0.0.1 - - [27/Jul/2020 09:03:07] "[37mPOST /api/v1/addmedia HTTP/1.1[0m" 200 -
2020-07-27 09:03:07,863 - werkzeug - INFO - 127.0.0.1 - - [27/Jul/2020 09:03:07] "[37mPOST /api/v1/addmedia HTTP/1.1[0m" 200 -
2020-07-27 09:03:46,203 - werkzeug - INFO -  * Detected change in 'C:\\work\\github\\whereismyshow\\DataAccess\\Services\\media_service.py', reloading
2020-07-27 09:03:46,203 - werkzeug - INFO -  * Detected change in 'C:\\work\\github\\whereismyshow\\DataAccess\\Services\\media_service.py', reloading
2020-07-27 09:03:46,311 - werkzeug - INFO -  * Restarting with stat
2020-07-27 09:03:46,311 - werkzeug - INFO -  * Restarting with stat
2020-07-27 09:03:48,889 - werkzeug - WARNING -  * Debugger is active!
2020-07-27 09:03:48,889 - werkzeug - WARNING -  * Debugger is active!
2020-07-27 09:03:48,904 - werkzeug - INFO -  * Debugger PIN: 273-249-106
2020-07-27 09:03:48,904 - werkzeug - INFO -  * Debugger PIN: 273-249-106
2020-07-27 09:03:48,926 - werkzeug - INFO -  * Running on http://127.0.0.1:5000/ (Press CTRL+C to quit)
2020-07-27 09:03:48,926 - werkzeug - INFO -  * Running on http://127.0.0.1:5000/ (Press CTRL+C to quit)
2020-07-27 09:03:51,270 - werkzeug - INFO -  * Detected change in 'C:\\work\\github\\whereismyshow\\DataAccess\\Services\\media_service.py', reloading
2020-07-27 09:03:51,270 - werkzeug - INFO -  * Detected change in 'C:\\work\\github\\whereismyshow\\DataAccess\\Services\\media_service.py', reloading
2020-07-27 09:03:51,500 - werkzeug - INFO -  * Restarting with stat
2020-07-27 09:03:51,500 - werkzeug - INFO -  * Restarting with stat
2020-07-27 09:03:54,192 - werkzeug - WARNING -  * Debugger is active!
2020-07-27 09:03:54,192 - werkzeug - WARNING -  * Debugger is active!
2020-07-27 09:03:54,202 - werkzeug - INFO -  * Debugger PIN: 273-249-106
2020-07-27 09:03:54,202 - werkzeug - INFO -  * Debugger PIN: 273-249-106
2020-07-27 09:03:54,218 - werkzeug - INFO -  * Running on http://127.0.0.1:5000/ (Press CTRL+C to quit)
2020-07-27 09:03:54,218 - werkzeug - INFO -  * Running on http://127.0.0.1:5000/ (Press CTRL+C to quit)
2020-07-27 09:05:02,933 - werkzeug - INFO -  * Detected change in 'C:\\work\\github\\whereismyshow\\DataAccess\\Services\\media_service.py', reloading
2020-07-27 09:05:02,933 - werkzeug - INFO -  * Detected change in 'C:\\work\\github\\whereismyshow\\DataAccess\\Services\\media_service.py', reloading
2020-07-27 09:05:03,205 - werkzeug - INFO -  * Restarting with stat
2020-07-27 09:05:03,205 - werkzeug - INFO -  * Restarting with stat
2020-07-27 09:05:36,305 - werkzeug - INFO -  * Restarting with stat
2020-07-27 09:05:36,305 - werkzeug - INFO -  * Restarting with stat
2020-07-27 09:05:38,394 - werkzeug - WARNING -  * Debugger is active!
2020-07-27 09:05:38,394 - werkzeug - WARNING -  * Debugger is active!
2020-07-27 09:05:38,404 - werkzeug - INFO -  * Debugger PIN: 273-249-106
2020-07-27 09:05:38,404 - werkzeug - INFO -  * Debugger PIN: 273-249-106
2020-07-27 09:05:38,422 - werkzeug - INFO -  * Running on http://127.0.0.1:5000/ (Press CTRL+C to quit)
2020-07-27 09:05:38,422 - werkzeug - INFO -  * Running on http://127.0.0.1:5000/ (Press CTRL+C to quit)
2020-07-27 09:05:44,118 - werkzeug - INFO - 127.0.0.1 - - [27/Jul/2020 09:05:44] "[35m[1mPOST /api/v1/addmedia HTTP/1.1[0m" 500 -
2020-07-27 09:05:44,118 - werkzeug - INFO - 127.0.0.1 - - [27/Jul/2020 09:05:44] "[35m[1mPOST /api/v1/addmedia HTTP/1.1[0m" 500 -
2020-07-27 09:08:23,253 - werkzeug - INFO - 127.0.0.1 - - [27/Jul/2020 09:08:23] "[35m[1mPOST /api/v1/addmedia HTTP/1.1[0m" 500 -
2020-07-27 09:08:23,253 - werkzeug - INFO - 127.0.0.1 - - [27/Jul/2020 09:08:23] "[35m[1mPOST /api/v1/addmedia HTTP/1.1[0m" 500 -
2020-07-27 09:09:06,343 - werkzeug - INFO - 127.0.0.1 - - [27/Jul/2020 09:09:06] "[35m[1mPOST /api/v1/addmedia HTTP/1.1[0m" 500 -
2020-07-27 09:09:06,343 - werkzeug - INFO - 127.0.0.1 - - [27/Jul/2020 09:09:06] "[35m[1mPOST /api/v1/addmedia HTTP/1.1[0m" 500 -
2020-07-27 09:11:27,762 - werkzeug - INFO -  * Detected change in 'C:\\work\\github\\whereismyshow\\DataAccess\\Services\\media_service.py', reloading
2020-07-27 09:11:27,762 - werkzeug - INFO -  * Detected change in 'C:\\work\\github\\whereismyshow\\DataAccess\\Services\\media_service.py', reloading
2020-07-27 09:11:27,914 - werkzeug - INFO -  * Restarting with stat
2020-07-27 09:11:27,914 - werkzeug - INFO -  * Restarting with stat
2020-07-27 09:11:29,928 - werkzeug - WARNING -  * Debugger is active!
2020-07-27 09:11:29,928 - werkzeug - WARNING -  * Debugger is active!
2020-07-27 09:11:29,937 - werkzeug - INFO -  * Debugger PIN: 273-249-106
2020-07-27 09:11:29,937 - werkzeug - INFO -  * Debugger PIN: 273-249-106
2020-07-27 09:11:29,956 - werkzeug - INFO -  * Running on http://127.0.0.1:5000/ (Press CTRL+C to quit)
2020-07-27 09:11:29,956 - werkzeug - INFO -  * Running on http://127.0.0.1:5000/ (Press CTRL+C to quit)
2020-07-27 09:12:00,283 - root - ERROR - Exception while parsing media json
count() takes exactly one argument (0 given)
Traceback (most recent call last):
  File "C:\work\github\whereismyshow\DataAccess\Services\media_service.py", line 101, in add_media
    if titles.count() == 0:
TypeError: count() takes exactly one argument (0 given)
2020-07-27 09:12:00,283 - root - ERROR - Exception while parsing media json
count() takes exactly one argument (0 given)
Traceback (most recent call last):
  File "C:\work\github\whereismyshow\DataAccess\Services\media_service.py", line 101, in add_media
    if titles.count() == 0:
TypeError: count() takes exactly one argument (0 given)
2020-07-27 09:12:00,316 - werkzeug - INFO - 127.0.0.1 - - [27/Jul/2020 09:12:00] "[35m[1mPOST /api/v1/addmedia HTTP/1.1[0m" 500 -
2020-07-27 09:12:00,316 - werkzeug - INFO - 127.0.0.1 - - [27/Jul/2020 09:12:00] "[35m[1mPOST /api/v1/addmedia HTTP/1.1[0m" 500 -
2020-07-27 09:14:33,651 - werkzeug - INFO -  * Restarting with stat
2020-07-27 09:14:33,651 - werkzeug - INFO -  * Restarting with stat
2020-07-27 09:14:35,623 - werkzeug - WARNING -  * Debugger is active!
2020-07-27 09:14:35,623 - werkzeug - WARNING -  * Debugger is active!
2020-07-27 09:14:35,631 - werkzeug - INFO -  * Debugger PIN: 273-249-106
2020-07-27 09:14:35,631 - werkzeug - INFO -  * Debugger PIN: 273-249-106
2020-07-27 09:14:35,646 - werkzeug - INFO -  * Running on http://127.0.0.1:5000/ (Press CTRL+C to quit)
2020-07-27 09:14:35,646 - werkzeug - INFO -  * Running on http://127.0.0.1:5000/ (Press CTRL+C to quit)
2020-07-27 09:15:36,464 - werkzeug - INFO -  * Restarting with stat
2020-07-27 09:15:36,464 - werkzeug - INFO -  * Restarting with stat
2020-07-27 09:15:38,663 - werkzeug - WARNING -  * Debugger is active!
2020-07-27 09:15:38,663 - werkzeug - WARNING -  * Debugger is active!
2020-07-27 09:15:38,674 - werkzeug - INFO -  * Debugger PIN: 273-249-106
2020-07-27 09:15:38,674 - werkzeug - INFO -  * Debugger PIN: 273-249-106
2020-07-27 09:15:38,693 - werkzeug - INFO -  * Running on http://127.0.0.1:5000/ (Press CTRL+C to quit)
2020-07-27 09:15:38,693 - werkzeug - INFO -  * Running on http://127.0.0.1:5000/ (Press CTRL+C to quit)
2020-07-27 09:15:42,921 - werkzeug - INFO - 127.0.0.1 - - [27/Jul/2020 09:15:42] "[37mPOST /api/v1/addmedia HTTP/1.1[0m" 200 -
2020-07-27 09:15:42,921 - werkzeug - INFO - 127.0.0.1 - - [27/Jul/2020 09:15:42] "[37mPOST /api/v1/addmedia HTTP/1.1[0m" 200 -
2020-07-27 17:00:01,248 - werkzeug - INFO -  * Restarting with stat
2020-07-27 17:00:01,248 - werkzeug - INFO -  * Restarting with stat
2020-07-27 17:00:02,300 - werkzeug - WARNING -  * Debugger is active!
2020-07-27 17:00:02,300 - werkzeug - WARNING -  * Debugger is active!
2020-07-27 17:00:02,314 - werkzeug - INFO -  * Debugger PIN: 273-249-106
2020-07-27 17:00:02,314 - werkzeug - INFO -  * Debugger PIN: 273-249-106
2020-07-27 17:00:02,326 - werkzeug - INFO -  * Running on http://127.0.0.1:5000/ (Press CTRL+C to quit)
2020-07-27 17:00:02,326 - werkzeug - INFO -  * Running on http://127.0.0.1:5000/ (Press CTRL+C to quit)
2020-07-27 17:00:32,086 - root - ERROR - Exception while parsing media json
Instance <Title at 0x18b53f1ac88> is not bound to a Session; attribute refresh operation cannot proceed (Background on this error at: http://sqlalche.me/e/13/bhk3)
Traceback (most recent call last):
  File "C:\work\github\whereismyshow\DataAccess\Services\media_service.py", line 80, in add_media
    title_provider = TitleProvider(title.id, provider.id, show["Provider"]["Url"])
  File "C:\Users\vlekkala\AppData\Local\Programs\Python\Python36\lib\site-packages\sqlalchemy\orm\attributes.py", line 287, in __get__
    return self.impl.get(instance_state(instance), dict_)
  File "C:\Users\vlekkala\AppData\Local\Programs\Python\Python36\lib\site-packages\sqlalchemy\orm\attributes.py", line 718, in get
    value = state._load_expired(state, passive)
  File "C:\Users\vlekkala\AppData\Local\Programs\Python\Python36\lib\site-packages\sqlalchemy\orm\state.py", line 652, in _load_expired
    self.manager.deferred_scalar_loader(self, toload)
  File "C:\Users\vlekkala\AppData\Local\Programs\Python\Python36\lib\site-packages\sqlalchemy\orm\loading.py", line 946, in load_scalar_attributes
    "attribute refresh operation cannot proceed" % (state_str(state))
sqlalchemy.orm.exc.DetachedInstanceError: Instance <Title at 0x18b53f1ac88> is not bound to a Session; attribute refresh operation cannot proceed (Background on this error at: http://sqlalche.me/e/13/bhk3)
2020-07-27 17:00:32,086 - root - ERROR - Exception while parsing media json
Instance <Title at 0x18b53f1ac88> is not bound to a Session; attribute refresh operation cannot proceed (Background on this error at: http://sqlalche.me/e/13/bhk3)
Traceback (most recent call last):
  File "C:\work\github\whereismyshow\DataAccess\Services\media_service.py", line 80, in add_media
    title_provider = TitleProvider(title.id, provider.id, show["Provider"]["Url"])
  File "C:\Users\vlekkala\AppData\Local\Programs\Python\Python36\lib\site-packages\sqlalchemy\orm\attributes.py", line 287, in __get__
    return self.impl.get(instance_state(instance), dict_)
  File "C:\Users\vlekkala\AppData\Local\Programs\Python\Python36\lib\site-packages\sqlalchemy\orm\attributes.py", line 718, in get
    value = state._load_expired(state, passive)
  File "C:\Users\vlekkala\AppData\Local\Programs\Python\Python36\lib\site-packages\sqlalchemy\orm\state.py", line 652, in _load_expired
    self.manager.deferred_scalar_loader(self, toload)
  File "C:\Users\vlekkala\AppData\Local\Programs\Python\Python36\lib\site-packages\sqlalchemy\orm\loading.py", line 946, in load_scalar_attributes
    "attribute refresh operation cannot proceed" % (state_str(state))
sqlalchemy.orm.exc.DetachedInstanceError: Instance <Title at 0x18b53f1ac88> is not bound to a Session; attribute refresh operation cannot proceed (Background on this error at: http://sqlalche.me/e/13/bhk3)
2020-07-27 17:00:32,129 - werkzeug - INFO - 127.0.0.1 - - [27/Jul/2020 17:00:32] "[35m[1mPOST /api/v1/addmedia HTTP/1.1[0m" 500 -
2020-07-27 17:00:32,129 - werkzeug - INFO - 127.0.0.1 - - [27/Jul/2020 17:00:32] "[35m[1mPOST /api/v1/addmedia HTTP/1.1[0m" 500 -
2020-07-27 17:01:37,117 - werkzeug - INFO -  * Restarting with stat
2020-07-27 17:01:37,117 - werkzeug - INFO -  * Restarting with stat
2020-07-27 17:01:39,157 - werkzeug - WARNING -  * Debugger is active!
2020-07-27 17:01:39,157 - werkzeug - WARNING -  * Debugger is active!
2020-07-27 17:01:39,176 - werkzeug - INFO -  * Debugger PIN: 273-249-106
2020-07-27 17:01:39,176 - werkzeug - INFO -  * Debugger PIN: 273-249-106
2020-07-27 17:01:39,190 - werkzeug - INFO -  * Running on http://127.0.0.1:5000/ (Press CTRL+C to quit)
2020-07-27 17:01:39,190 - werkzeug - INFO -  * Running on http://127.0.0.1:5000/ (Press CTRL+C to quit)
2020-07-27 17:02:02,908 - werkzeug - INFO - 127.0.0.1 - - [27/Jul/2020 17:02:02] "[37mPOST /api/v1/addmedia HTTP/1.1[0m" 200 -
2020-07-27 17:02:02,908 - werkzeug - INFO - 127.0.0.1 - - [27/Jul/2020 17:02:02] "[37mPOST /api/v1/addmedia HTTP/1.1[0m" 200 -
