2020-07-23 09:01:59,272 - root - ERROR - Exception occurred while adding a entity.
(psycopg2.errors.UndefinedTable) relation "dbo.title" does not exist
LINE 1: INSERT INTO "dbo.title" (title_id, picture, name, inserted_d...
                    ^
 [SQL: 'INSERT INTO "dbo.title" (title_id, picture, name, inserted_date) VALUES (%(title_id)s, %(picture)s, %(name)s, %(inserted_date)s) RETURNING "dbo.title".id'] [parameters: {'title_id': '5d91416b302b840050ad2718', 'picture': 'https://utellyassets9-1.imgix.net/api/Images/8698c96ae0e0038b81b661c8b2068ca1/Redirect', 'name': 'Lucifer', 'inserted_date': None}] (Background on this error at: http://sqlalche.me/e/f405)
Traceback (most recent call last):
  File "C:\Users\vlekkala\AppData\Local\Programs\Python\Python36\lib\site-packages\sqlalchemy\engine\base.py", line 1193, in _execute_context
    context)
  File "C:\Users\vlekkala\AppData\Local\Programs\Python\Python36\lib\site-packages\sqlalchemy\engine\default.py", line 507, in do_execute
    cursor.execute(statement, parameters)
psycopg2.errors.UndefinedTable: relation "dbo.title" does not exist
LINE 1: INSERT INTO "dbo.title" (title_id, picture, name, inserted_d...
                    ^


The above exception was the direct cause of the following exception:

Traceback (most recent call last):
  File "C:\work\github\whereismyshow\DataAccess\Base\repository_base.py", line 59, in AddBulk
    session.commit()
  File "C:\Users\vlekkala\AppData\Local\Programs\Python\Python36\lib\site-packages\sqlalchemy\orm\session.py", line 937, in commit
    self.transaction.commit()
  File "C:\Users\vlekkala\AppData\Local\Programs\Python\Python36\lib\site-packages\sqlalchemy\orm\session.py", line 461, in commit
    self._prepare_impl()
  File "C:\Users\vlekkala\AppData\Local\Programs\Python\Python36\lib\site-packages\sqlalchemy\orm\session.py", line 441, in _prepare_impl
    self.session.flush()
  File "C:\Users\vlekkala\AppData\Local\Programs\Python\Python36\lib\site-packages\sqlalchemy\orm\session.py", line 2237, in flush
    self._flush(objects)
  File "C:\Users\vlekkala\AppData\Local\Programs\Python\Python36\lib\site-packages\sqlalchemy\orm\session.py", line 2363, in _flush
    transaction.rollback(_capture_exception=True)
  File "C:\Users\vlekkala\AppData\Local\Programs\Python\Python36\lib\site-packages\sqlalchemy\util\langhelpers.py", line 66, in __exit__
    compat.reraise(exc_type, exc_value, exc_tb)
  File "C:\Users\vlekkala\AppData\Local\Programs\Python\Python36\lib\site-packages\sqlalchemy\util\compat.py", line 187, in reraise
    raise value
  File "C:\Users\vlekkala\AppData\Local\Programs\Python\Python36\lib\site-packages\sqlalchemy\orm\session.py", line 2327, in _flush
    flush_context.execute()
  File "C:\Users\vlekkala\AppData\Local\Programs\Python\Python36\lib\site-packages\sqlalchemy\orm\unitofwork.py", line 391, in execute
    rec.execute(self)
  File "C:\Users\vlekkala\AppData\Local\Programs\Python\Python36\lib\site-packages\sqlalchemy\orm\unitofwork.py", line 556, in execute
    uow
  File "C:\Users\vlekkala\AppData\Local\Programs\Python\Python36\lib\site-packages\sqlalchemy\orm\persistence.py", line 181, in save_obj
    mapper, table, insert)
  File "C:\Users\vlekkala\AppData\Local\Programs\Python\Python36\lib\site-packages\sqlalchemy\orm\persistence.py", line 866, in _emit_insert_statements
    execute(statement, params)
  File "C:\Users\vlekkala\AppData\Local\Programs\Python\Python36\lib\site-packages\sqlalchemy\engine\base.py", line 948, in execute
    return meth(self, multiparams, params)
  File "C:\Users\vlekkala\AppData\Local\Programs\Python\Python36\lib\site-packages\sqlalchemy\sql\elements.py", line 269, in _execute_on_connection
    return connection._execute_clauseelement(self, multiparams, params)
  File "C:\Users\vlekkala\AppData\Local\Programs\Python\Python36\lib\site-packages\sqlalchemy\engine\base.py", line 1060, in _execute_clauseelement
    compiled_sql, distilled_params
  File "C:\Users\vlekkala\AppData\Local\Programs\Python\Python36\lib\site-packages\sqlalchemy\engine\base.py", line 1200, in _execute_context
    context)
  File "C:\Users\vlekkala\AppData\Local\Programs\Python\Python36\lib\site-packages\sqlalchemy\engine\base.py", line 1413, in _handle_dbapi_exception
    exc_info
  File "C:\Users\vlekkala\AppData\Local\Programs\Python\Python36\lib\site-packages\sqlalchemy\util\compat.py", line 203, in raise_from_cause
    reraise(type(exception), exception, tb=exc_tb, cause=cause)
  File "C:\Users\vlekkala\AppData\Local\Programs\Python\Python36\lib\site-packages\sqlalchemy\util\compat.py", line 186, in reraise
    raise value.with_traceback(tb)
  File "C:\Users\vlekkala\AppData\Local\Programs\Python\Python36\lib\site-packages\sqlalchemy\engine\base.py", line 1193, in _execute_context
    context)
  File "C:\Users\vlekkala\AppData\Local\Programs\Python\Python36\lib\site-packages\sqlalchemy\engine\default.py", line 507, in do_execute
    cursor.execute(statement, parameters)
sqlalchemy.exc.ProgrammingError: (psycopg2.errors.UndefinedTable) relation "dbo.title" does not exist
LINE 1: INSERT INTO "dbo.title" (title_id, picture, name, inserted_d...
                    ^
 [SQL: 'INSERT INTO "dbo.title" (title_id, picture, name, inserted_date) VALUES (%(title_id)s, %(picture)s, %(name)s, %(inserted_date)s) RETURNING "dbo.title".id'] [parameters: {'title_id': '5d91416b302b840050ad2718', 'picture': 'https://utellyassets9-1.imgix.net/api/Images/8698c96ae0e0038b81b661c8b2068ca1/Redirect', 'name': 'Lucifer', 'inserted_date': None}] (Background on this error at: http://sqlalche.me/e/f405)
2020-07-23 20:31:42,429 - root - ERROR - Exception occurred while adding a entity.
(psycopg2.errors.UndefinedTable) relation "title" does not exist
LINE 1: INSERT INTO title (title_id, picture, name, inserted_date) V...
                    ^
 [SQL: 'INSERT INTO title (title_id, picture, name, inserted_date) VALUES (%(title_id)s, %(picture)s, %(name)s, %(inserted_date)s) RETURNING title.id'] [parameters: {'title_id': '5d91416b302b840050ad2718', 'picture': 'https://utellyassets9-1.imgix.net/api/Images/8698c96ae0e0038b81b661c8b2068ca1/Redirect', 'name': 'Lucifer', 'inserted_date': None}] (Background on this error at: http://sqlalche.me/e/f405)
Traceback (most recent call last):
  File "C:\Users\vlekkala\AppData\Local\Programs\Python\Python36\lib\site-packages\sqlalchemy\engine\base.py", line 1193, in _execute_context
    context)
  File "C:\Users\vlekkala\AppData\Local\Programs\Python\Python36\lib\site-packages\sqlalchemy\engine\default.py", line 507, in do_execute
    cursor.execute(statement, parameters)
psycopg2.errors.UndefinedTable: relation "title" does not exist
LINE 1: INSERT INTO title (title_id, picture, name, inserted_date) V...
                    ^


The above exception was the direct cause of the following exception:

Traceback (most recent call last):
  File "C:\work\github\whereismyshow\DataAccess\Base\repository_base.py", line 59, in AddBulk
    session.commit()
  File "C:\Users\vlekkala\AppData\Local\Programs\Python\Python36\lib\site-packages\sqlalchemy\orm\session.py", line 937, in commit
    self.transaction.commit()
  File "C:\Users\vlekkala\AppData\Local\Programs\Python\Python36\lib\site-packages\sqlalchemy\orm\session.py", line 461, in commit
    self._prepare_impl()
  File "C:\Users\vlekkala\AppData\Local\Programs\Python\Python36\lib\site-packages\sqlalchemy\orm\session.py", line 441, in _prepare_impl
    self.session.flush()
  File "C:\Users\vlekkala\AppData\Local\Programs\Python\Python36\lib\site-packages\sqlalchemy\orm\session.py", line 2237, in flush
    self._flush(objects)
  File "C:\Users\vlekkala\AppData\Local\Programs\Python\Python36\lib\site-packages\sqlalchemy\orm\session.py", line 2363, in _flush
    transaction.rollback(_capture_exception=True)
  File "C:\Users\vlekkala\AppData\Local\Programs\Python\Python36\lib\site-packages\sqlalchemy\util\langhelpers.py", line 66, in __exit__
    compat.reraise(exc_type, exc_value, exc_tb)
  File "C:\Users\vlekkala\AppData\Local\Programs\Python\Python36\lib\site-packages\sqlalchemy\util\compat.py", line 187, in reraise
    raise value
  File "C:\Users\vlekkala\AppData\Local\Programs\Python\Python36\lib\site-packages\sqlalchemy\orm\session.py", line 2327, in _flush
    flush_context.execute()
  File "C:\Users\vlekkala\AppData\Local\Programs\Python\Python36\lib\site-packages\sqlalchemy\orm\unitofwork.py", line 391, in execute
    rec.execute(self)
  File "C:\Users\vlekkala\AppData\Local\Programs\Python\Python36\lib\site-packages\sqlalchemy\orm\unitofwork.py", line 556, in execute
    uow
  File "C:\Users\vlekkala\AppData\Local\Programs\Python\Python36\lib\site-packages\sqlalchemy\orm\persistence.py", line 181, in save_obj
    mapper, table, insert)
  File "C:\Users\vlekkala\AppData\Local\Programs\Python\Python36\lib\site-packages\sqlalchemy\orm\persistence.py", line 866, in _emit_insert_statements
    execute(statement, params)
  File "C:\Users\vlekkala\AppData\Local\Programs\Python\Python36\lib\site-packages\sqlalchemy\engine\base.py", line 948, in execute
    return meth(self, multiparams, params)
  File "C:\Users\vlekkala\AppData\Local\Programs\Python\Python36\lib\site-packages\sqlalchemy\sql\elements.py", line 269, in _execute_on_connection
    return connection._execute_clauseelement(self, multiparams, params)
  File "C:\Users\vlekkala\AppData\Local\Programs\Python\Python36\lib\site-packages\sqlalchemy\engine\base.py", line 1060, in _execute_clauseelement
    compiled_sql, distilled_params
  File "C:\Users\vlekkala\AppData\Local\Programs\Python\Python36\lib\site-packages\sqlalchemy\engine\base.py", line 1200, in _execute_context
    context)
  File "C:\Users\vlekkala\AppData\Local\Programs\Python\Python36\lib\site-packages\sqlalchemy\engine\base.py", line 1413, in _handle_dbapi_exception
    exc_info
  File "C:\Users\vlekkala\AppData\Local\Programs\Python\Python36\lib\site-packages\sqlalchemy\util\compat.py", line 203, in raise_from_cause
    reraise(type(exception), exception, tb=exc_tb, cause=cause)
  File "C:\Users\vlekkala\AppData\Local\Programs\Python\Python36\lib\site-packages\sqlalchemy\util\compat.py", line 186, in reraise
    raise value.with_traceback(tb)
  File "C:\Users\vlekkala\AppData\Local\Programs\Python\Python36\lib\site-packages\sqlalchemy\engine\base.py", line 1193, in _execute_context
    context)
  File "C:\Users\vlekkala\AppData\Local\Programs\Python\Python36\lib\site-packages\sqlalchemy\engine\default.py", line 507, in do_execute
    cursor.execute(statement, parameters)
sqlalchemy.exc.ProgrammingError: (psycopg2.errors.UndefinedTable) relation "title" does not exist
LINE 1: INSERT INTO title (title_id, picture, name, inserted_date) V...
                    ^
 [SQL: 'INSERT INTO title (title_id, picture, name, inserted_date) VALUES (%(title_id)s, %(picture)s, %(name)s, %(inserted_date)s) RETURNING title.id'] [parameters: {'title_id': '5d91416b302b840050ad2718', 'picture': 'https://utellyassets9-1.imgix.net/api/Images/8698c96ae0e0038b81b661c8b2068ca1/Redirect', 'name': 'Lucifer', 'inserted_date': None}] (Background on this error at: http://sqlalche.me/e/f405)
2020-07-23 20:33:38,560 - root - ERROR - Exception occurred while adding a entity.
(psycopg2.errors.UndefinedTable) relation "title" does not exist
LINE 1: INSERT INTO title (title_id, picture, name, inserted_date) V...
                    ^

[SQL: INSERT INTO title (title_id, picture, name, inserted_date) VALUES (%(title_id)s, %(picture)s, %(name)s, %(inserted_date)s) RETURNING title.id]
[parameters: {'title_id': '5d91416b302b840050ad2718', 'picture': 'https://utellyassets9-1.imgix.net/api/Images/8698c96ae0e0038b81b661c8b2068ca1/Redirect', 'name': 'Lucifer', 'inserted_date': None}]
(Background on this error at: http://sqlalche.me/e/13/f405)
Traceback (most recent call last):
  File "C:\Users\vlekkala\AppData\Local\Programs\Python\Python36\lib\site-packages\sqlalchemy\engine\base.py", line 1278, in _execute_context
    cursor, statement, parameters, context
  File "C:\Users\vlekkala\AppData\Local\Programs\Python\Python36\lib\site-packages\sqlalchemy\engine\default.py", line 593, in do_execute
    cursor.execute(statement, parameters)
psycopg2.errors.UndefinedTable: relation "title" does not exist
LINE 1: INSERT INTO title (title_id, picture, name, inserted_date) V...
                    ^


The above exception was the direct cause of the following exception:

Traceback (most recent call last):
  File "C:\work\github\whereismyshow\DataAccess\Base\repository_base.py", line 59, in AddBulk
    session.commit()
  File "C:\Users\vlekkala\AppData\Local\Programs\Python\Python36\lib\site-packages\sqlalchemy\orm\session.py", line 1042, in commit
    self.transaction.commit()
  File "C:\Users\vlekkala\AppData\Local\Programs\Python\Python36\lib\site-packages\sqlalchemy\orm\session.py", line 504, in commit
    self._prepare_impl()
  File "C:\Users\vlekkala\AppData\Local\Programs\Python\Python36\lib\site-packages\sqlalchemy\orm\session.py", line 483, in _prepare_impl
    self.session.flush()
  File "C:\Users\vlekkala\AppData\Local\Programs\Python\Python36\lib\site-packages\sqlalchemy\orm\session.py", line 2523, in flush
    self._flush(objects)
  File "C:\Users\vlekkala\AppData\Local\Programs\Python\Python36\lib\site-packages\sqlalchemy\orm\session.py", line 2664, in _flush
    transaction.rollback(_capture_exception=True)
  File "C:\Users\vlekkala\AppData\Local\Programs\Python\Python36\lib\site-packages\sqlalchemy\util\langhelpers.py", line 69, in __exit__
    exc_value, with_traceback=exc_tb,
  File "C:\Users\vlekkala\AppData\Local\Programs\Python\Python36\lib\site-packages\sqlalchemy\util\compat.py", line 178, in raise_
    raise exception
  File "C:\Users\vlekkala\AppData\Local\Programs\Python\Python36\lib\site-packages\sqlalchemy\orm\session.py", line 2624, in _flush
    flush_context.execute()
  File "C:\Users\vlekkala\AppData\Local\Programs\Python\Python36\lib\site-packages\sqlalchemy\orm\unitofwork.py", line 422, in execute
    rec.execute(self)
  File "C:\Users\vlekkala\AppData\Local\Programs\Python\Python36\lib\site-packages\sqlalchemy\orm\unitofwork.py", line 589, in execute
    uow,
  File "C:\Users\vlekkala\AppData\Local\Programs\Python\Python36\lib\site-packages\sqlalchemy\orm\persistence.py", line 245, in save_obj
    insert,
  File "C:\Users\vlekkala\AppData\Local\Programs\Python\Python36\lib\site-packages\sqlalchemy\orm\persistence.py", line 1136, in _emit_insert_statements
    statement, params
  File "C:\Users\vlekkala\AppData\Local\Programs\Python\Python36\lib\site-packages\sqlalchemy\engine\base.py", line 1014, in execute
    return meth(self, multiparams, params)
  File "C:\Users\vlekkala\AppData\Local\Programs\Python\Python36\lib\site-packages\sqlalchemy\sql\elements.py", line 298, in _execute_on_connection
    return connection._execute_clauseelement(self, multiparams, params)
  File "C:\Users\vlekkala\AppData\Local\Programs\Python\Python36\lib\site-packages\sqlalchemy\engine\base.py", line 1133, in _execute_clauseelement
    distilled_params,
  File "C:\Users\vlekkala\AppData\Local\Programs\Python\Python36\lib\site-packages\sqlalchemy\engine\base.py", line 1318, in _execute_context
    e, statement, parameters, cursor, context
  File "C:\Users\vlekkala\AppData\Local\Programs\Python\Python36\lib\site-packages\sqlalchemy\engine\base.py", line 1512, in _handle_dbapi_exception
    sqlalchemy_exception, with_traceback=exc_info[2], from_=e
  File "C:\Users\vlekkala\AppData\Local\Programs\Python\Python36\lib\site-packages\sqlalchemy\util\compat.py", line 178, in raise_
    raise exception
  File "C:\Users\vlekkala\AppData\Local\Programs\Python\Python36\lib\site-packages\sqlalchemy\engine\base.py", line 1278, in _execute_context
    cursor, statement, parameters, context
  File "C:\Users\vlekkala\AppData\Local\Programs\Python\Python36\lib\site-packages\sqlalchemy\engine\default.py", line 593, in do_execute
    cursor.execute(statement, parameters)
sqlalchemy.exc.ProgrammingError: (psycopg2.errors.UndefinedTable) relation "title" does not exist
LINE 1: INSERT INTO title (title_id, picture, name, inserted_date) V...
                    ^

[SQL: INSERT INTO title (title_id, picture, name, inserted_date) VALUES (%(title_id)s, %(picture)s, %(name)s, %(inserted_date)s) RETURNING title.id]
[parameters: {'title_id': '5d91416b302b840050ad2718', 'picture': 'https://utellyassets9-1.imgix.net/api/Images/8698c96ae0e0038b81b661c8b2068ca1/Redirect', 'name': 'Lucifer', 'inserted_date': None}]
(Background on this error at: http://sqlalche.me/e/13/f405)
